Workbook

Sheet Test Cases
A1: Dummy Resources (PSD v2) — Test Cases
A2: Source: resources/product-specifications-document/AgriERP FSCM - Dummy Resources v2.pdf. Plan: playwright/test-plans/authenticated/dummy-resources.md. Updated 2026-09-30: ADO #26191 impact areas added (DRI-01..06); v2 released on QA, web cases re-verified live (FINDINGS #47–#49); cross-checked against client sheet AgriERP_Dummy_Resource_Test_Cases.xlsx.
A3: Legend: Change — green = New, yellow = Updated (PSD revision 2026-09-29), white = Existing. Fill in the Result column (Pass / Fail / Blocked / Not Run) when executing. Results pre-filled from the 2026-09-30 automated runs on QA (web UI + DummyShift API; DRM results cover the server rules, not the mobile screens).
A5: ID | B5: Title | C5: Change | D5: Section | E5: Role | F5: Platform | G5: Priority | H5: Type | I5: Preconditions | J5: Steps | K5: Test data | L5: Expected result | M5: PSD reference | N5: Automation | O5: Notes | P5: Client TC IDs | Q5: Result
A6: DR-01 | B6: A dummy resource on the web form takes no quantity (entered on mobile at Start Job) | C6: Updated | D6: Selecting dummy resources | E6: Admin / Manager | F6: Web | G6: P1 | H6: Functional / Smoke | I6: Logged in to the Farm Web App as Admin / Manager (VBS tenant, QA env). Work Orders → Create New Work Order (Planned) is open with Farm, Operation and Plot set — Add Resources stays inert until all three are set. | J6: 1. Click '+' → Add Dummy Resource. 2. Tick a dummy resource and Save. 3. Look at the resource row and the grid's columns. | K6: Machine Operator (DM001) | L6: The row is added with the DUMMY RESOURCE badge; the grid has no No Of Resource column and the row has no number input. The quantity is entered on the mobile app when the job starts. | M6: AgriERP FSCM - Dummy Resources v2.pdf — Figure 1 (p.7) mock; Farm Operations Manager journey steps 3–8 (p.25) | N6: ✅ Automated | O6: Corrected 2026-09-30: FINDINGS #47 / ADO #26454 withdrawn — the quantity is not a web field. | P6: — | Q6: Pass
A7: DR-02 | B7: Select Resources '+' offers Add Resource and Add Dummy Resource | C7: Existing | D7: Selecting dummy resources | E7: Admin / Manager | F7: Web | G7: P2 | H7: Functional | I7: Logged in to the Farm Web App as Admin / Manager (VBS tenant, QA env). Work Orders → Create New Work Order (Planned) is open with Farm, Operation and Plot set — Add Resources stays inert until all three are set. | J7: 1. On the Select Resources header, click the '+' icon. | K7: — | L7: A dropdown opens with exactly two items: Add Resource and Add Dummy Resource (standard AgriERP menu style). | M7: AgriERP FSCM - Dummy Resources v2.pdf — Mocks, Figure 1 (p.7) | N7: ✅ Automated | O7: QA still serves v1 (FINDINGS #34). | P7: WEB-001 | Q7: Pass
A8: DR-03 | B8: Add Dummy Resource opens the dummy register | C8: Existing | D8: Selecting dummy resources | E8: Admin / Manager | F8: Web | G8: P2 | H8: Functional | I8: Logged in to the Farm Web App as Admin / Manager (VBS tenant, QA env). Work Orders → Create New Work Order (Planned) is open with Farm, Operation and Plot set — Add Resources stays inert until all three are set. | J8: 1. Click '+' → Add Dummy Resource. 2. Inspect the panel heading, filters and rows. | K8: — | L8: Panel heading reads Dummy Resource; Resource Group, Search By Resource Name and Search By Company Name filters present; no Dummy Resource Yes/No toggle; only the dummy register is listed (8 rows, e.g. Irrigator (DM002)). | M8: AgriERP FSCM - Dummy Resources v2.pdf — Figure 2 (p.8); Supervisor journey steps 4–5 | N8: ✅ Automated | P8: WEB-002, WEB-003, WEB-010 | Q8: Pass
A9: DR-04 | B9: Add Resource lists named resources only | C9: Existing | D9: Selecting dummy resources | E9: Admin / Manager | F9: Web | G9: P2 | H9: Functional / Negative | I9: Logged in to the Farm Web App as Admin / Manager (VBS tenant, QA env). Work Orders → Create New Work Order (Planned) is open with Farm, Operation and Plot set — Add Resources stays inert until all three are set. | J9: 1. Click '+' → Add Resource. 2. Inspect the rows and filters. | K9: — | L9: No Dummy Resource toggle; no row carries the Dummy Resource chip. | M9: AgriERP FSCM - Dummy Resources v2.pdf — Solution Overview (register chosen before the page opens) | N9: ✅ Automated | P9: WEB-003, WEB-009, WEB-010 | Q9: Pass
A10: DR-05 | B10: Dummy resource row on the form shows the yellow chip | C10: Existing | D10: Selecting dummy resources | E10: Admin / Manager | F10: Web | G10: P3 | H10: UI | I10: Logged in to the Farm Web App as Admin / Manager (VBS tenant, QA env). Work Orders → Create New Work Order (Planned) is open with Farm, Operation and Plot set — Add Resources stays inert until all three are set. A dummy resource has been added to the WO. | J10: 1. Look at the dummy resource row under Select Resources. | K10: Machine Operator (DM001) | L10: Row shows the yellow DUMMY RESOURCE badge (title Dummy Resource) beside the name. | M10: AgriERP FSCM - Dummy Resources v2.pdf — Figure 1 (p.7) | N10: ✅ Automated | P10: WEB-008 | Q10: Pass
A11: DR-06 | B11: RETIRED — web save blocked without a quantity | C11: Updated | D11: Validation | E11: Admin / Manager | F11: Web | G11: P3 | H11: — | I11: — | J11: — | K11: — | L11: Retired 2026-09-30: the quantity is not a web field (Figure 1; Manager journey steps 6–8). The Mandatory Fields rule applies at Start Job and is covered by DRM-04. | M11: AgriERP FSCM - Dummy Resources v2.pdf — Validation Rules → Mandatory Fields | N11: Retired — see DRM-04 (API) | O11: FINDINGS #47 withdrawn. | P11: — | Q11: Not Run
A12: DR-07 | B12: Dummy resource hours show on web: resource list, Spent Hours, WO logs, Hour Log Adjustment | C12: Updated | D12: Hours & integration | E12: Admin / Manager | F12: Web | G12: P2 | H12: Functional / Integration | I12: Logged in to the Farm Web App as Admin / Manager. An In Progress WO has at least one dummy resource shift logged on mobile. | J12: 1. Work Orders → In Progress chip → open the WO (eye icon). 2. Check the Resources list. 3. Open Spent Hours. 4. Open the work order logs. 5. Open Hour Log Adjustment for the resource. | K12: WO from `pnpm seed:hourlog` | L12: Dummy resource hours appear on the resource list, Spent Hours, the work order logs and Hour Log Adjustment, with headcount and standard hours, plus source (Web/Mobile), device and user. | M12: AgriERP FSCM - Dummy Resources v2.pdf — Dummy Resource Management (p.6); Integration with Hour Log Adjustment (p.23) | N12: Manual (needs a mobile shift); automatable afterwards | O12: 2026-09-30: work order logs added (client INT-006). | P12: INT-005, INT-006 | Q12: Not Run
A13: DR-08 | B13: Dummy + machine hours post to the WO's ERP project | C13: Existing | D13: Hours & integration | E13: Admin / Manager | F13: Web / D365 | G13: P1 | H13: Integration | I13: A WO with logged dummy resource shifts, linked to an ERP project; a second WO whose plot has no ERP project link. | J13: 1. Post the hours from the linked WO and check the project in D365. 2. Try to post from the unlinked WO. 3. Correct a shift before WO completion; check re-post. 4. Complete the WO and try to edit the hours. | K13: — | L13: Resource and machine/implement hours post to the WO's ERP project; posting is restricted without a project link; corrections before completion are re-posted; after completion hours are read-only. | M13: AgriERP FSCM - Dummy Resources v2.pdf — Integration with ERP (p.23) | N13: Partial: API posting readiness; D365 posting manual | O13: API check: GET /api/DummyShift/PostingReadiness/{workOrderId}, /UnpostableResources/{workOrderId} | P13: INT-001, INT-002, INT-003, INT-004 | Q13: Not Run
A14: DR-09 | B14: Named resource on a running job cannot be re-selected; dummy never blocked | C14: Existing | D14: Resource availability | E14: Admin / Manager | F14: Web | G14: P2 | H14: Negative | I14: Logged in to the Farm Web App as Admin / Manager. A named resource is working on a running job (not paused/stopped). | J14: 1. On another WO, open Add Resource and try to select the busy named resource. 2. Open Add Dummy Resource and select a dummy resource already on a running job. | K14: Named resource on a running job; any dummy resource | L14: The named resource cannot be selected until its job is paused or stopped; the dummy resource is selectable. | M14: AgriERP FSCM - Dummy Resources v2.pdf — Dummy Resource Management (p.6) | N14: Manual; web half automatable once a running job can be seeded | P14: VAL-004, VAL-005 | Q14: Not Run
A15: DR-10 | B15: In Progress WO on web stays In Progress and shows hours from every resumed shift | C15: New | D15: Resume Job & shifts | E15: Admin / Manager | F15: Web | G15: P1 | H15: Functional / Regression | I15: Logged in to the Farm Web App as Admin / Manager (VBS tenant, QA env). The In Progress WO from DRM-10 has Shift 1 and Shift 2 logged on mobile via Resume Job. | J15: 1. Open Work Orders and click the In Progress status chip. 2. Find the WO and click the eye icon (View). 3. Open the Resources section and read the dummy resource rows. 4. Open Spent Hours for the plot. | K15: WO from `pnpm seed:hourlog`; Shift 1: 2 res × 2 h; Shift 2: 1 res × 2 h | L15: The WO is listed under In Progress (not To Do or Queue). The resource list and Spent Hours show the hours of both shifts (4 h + 2 h = 6 h resource hours), with headcount and source Mobile. | M15: AgriERP FSCM - Dummy Resources v2.pdf — Important Point – Resume Job and Shifts (p.22); Dummy Resource Management (p.6) | N15: Manual; automatable later against a seeded WO (read-only) | O15: Derived: plot remains In Progress once started + shift hours are additive + hours visible on web. | P15: — | Q15: Not Run
A16: DR-11 | B16: Resource Group filter narrows the Add Dummy Resource list | C16: New | D16: Selecting dummy resources | E16: Admin / Manager | F16: Web | G16: P2 | H16: Functional | I16: Logged in to the Farm Web App as Admin / Manager (VBS tenant, QA env). Work Orders → Create New Work Order (Planned) is open with Farm, Operation and Plot set — Add Resources stays inert until all three are set. (v2 build, where the Select Resources "+" menu is deployed). | J16: 1. Click '+' → Add Dummy Resource. 2. Open the Resource Group dropdown (default All) and pick a group. 3. Click Apply. 4. Repeat on '+' → Add Resource. | K16: Resource Group: Machine Operators | L16: Only resources of the chosen group remain; the filter behaves the same on Add Resource. | M16: AgriERP FSCM - Dummy Resources v2.pdf — Figure 2 (p.8) — filters work the same way in both modes | N16: Manual — blocked by data (Resource Group offers only All) | P16: WEB-004 | Q16: Blocked
A17: DR-12 | B17: Search By Resource Name filters the dummy list | C17: New | D17: Selecting dummy resources | E17: Admin / Manager | F17: Web | G17: P3 | H17: Functional | I17: Logged in to the Farm Web App as Admin / Manager (VBS tenant, QA env). Work Orders → Create New Work Order (Planned) is open with Farm, Operation and Plot set — Add Resources stays inert until all three are set. (v2 build, where the Select Resources "+" menu is deployed). | J17: 1. Click '+' → Add Dummy Resource. 2. Type in Search By Resource Name. 3. Click Apply. | K17: "Irrigator" | L17: Only matching dummy resources remain (e.g. Irrigator (DM002), Irrigator 02 (DM003)). | M17: AgriERP FSCM - Dummy Resources v2.pdf — Figure 2 (p.8) | N17: ✅ Automated | P17: WEB-005 | Q17: Pass
A18: DR-13 | B18: Search By Company Name filters the dummy list | C18: New | D18: Selecting dummy resources | E18: Admin / Manager | F18: Web | G18: P3 | H18: Functional | I18: Logged in to the Farm Web App as Admin / Manager (VBS tenant, QA env). Work Orders → Create New Work Order (Planned) is open with Farm, Operation and Plot set — Add Resources stays inert until all three are set. (v2 build, where the Select Resources "+" menu is deployed). | J18: 1. Click '+' → Add Dummy Resource. 2. Type a company in Search By Company Name. 3. Click Apply. | K18: A company name shown in the Company column | L18: Only dummy resources tied to that company remain. | M18: AgriERP FSCM - Dummy Resources v2.pdf — Figure 2 (p.8) | N18: Manual — blocked by data (dummy resources have no Company Name) | P18: WEB-006 | Q18: Blocked
A19: DR-14 | B19: Reset clears the applied filters | C19: New | D19: Selecting dummy resources | E19: Admin / Manager | F19: Web | G19: P3 | H19: Functional | I19: Logged in to the Farm Web App as Admin / Manager (VBS tenant, QA env). Work Orders → Create New Work Order (Planned) is open with Farm, Operation and Plot set — Add Resources stays inert until all three are set. (v2 build, where the Select Resources "+" menu is deployed). | J19: 1. Click '+' → Add Dummy Resource. 2. Apply Resource Group, Resource Name and Company Name filters. 3. Click Reset. | K19: Any filter values | L19: All filters clear, Resource Group returns to All, and the full dummy register is listed again. | M19: AgriERP FSCM - Dummy Resources v2.pdf — Figure 2 (p.8) | N19: ❌ Expected failure — FINDINGS #48 (Reset switches to the named register) | O19: Reset is from the Select Resources modal (knowledge base); the PSD text names only the three filters. | P19: WEB-007 | Q19: Fail
A20: DR-15 | B20: Several dummy resources selected in one pass are all added | C20: New | D20: Selecting dummy resources | E20: Admin / Manager | F20: Web | G20: P1 | H20: Functional | I20: Logged in to the Farm Web App as Admin / Manager (VBS tenant, QA env). Work Orders → Create New Work Order (Planned) is open with Farm, Operation and Plot set — Add Resources stays inert until all three are set. | J20: 1. Open the dummy register (v2: '+' → Add Dummy Resource; v1: Dummy Resource switch = Yes). 2. Tick two dummy resources. 3. Click Save. | K20: Irrigator (DM002), Irrigator 02 (DM003) | L20: Both are added under Select Resources, each with its own No Of Resource input (and, on v2, the Dummy Resource chip). | M20: AgriERP FSCM - Dummy Resources v2.pdf — Figures 1–2 (p.7–8); Business Cases — added from the web during planning | N20: ✅ Automated (read-only) | P20: WEB-011 | Q20: Pass
A21: DR-16 | B21: Dummy resources are flagged master data in Resource Management | C21: New | D21: Selecting dummy resources | E21: Admin / Manager | F21: Web | G21: P2 | H21: Functional | I21: Logged in to the Farm Web App as Admin / Manager with access to Settings → Resources. | J21: 1. Open Settings → Resources. 2. Find a dummy resource (e.g. Irrigator (DM002)). 3. Open it and check its dummy flag. 4. Confirm it can be picked on a WO (DR-01). | K21: Irrigator (DM002) | L21: The record is stored as master data and flagged as dummy; it is selectable onto a WO like a named resource. | M21: AgriERP FSCM - Dummy Resources v2.pdf — Dummy Resource Management (p.6) | N21: Manual | O21: Screen and flag label unverified on QA; confirm the exact wording on first run. | P21: WEB-012 | Q21: Not Run
A22: DR-17 | B22: Dummy resource hours adjustable from Spent Hours until the WO is completed | C22: New | D22: Hours & integration | E22: Admin / Manager | F22: Web | G22: P1 | H22: Functional | I22: Logged in to the Farm Web App as Admin / Manager. An In Progress WO (`pnpm seed:hourlog`) has a dummy resource shift logged on mobile. | J22: 1. Work Orders → In Progress chip → open the WO. 2. In the Resources table, click the dummy resource's Hours Logged link to open Spent Hours. 3. Adjust the hours and save. 4. Re-read Spent Hours. | K22: Shift of 2 res × 2 h (4 h) adjusted to 3 h | L22: The adjustment is saved and Spent Hours shows the new value while the WO is not completed. (After completion hours are read-only — DR-08.) | M22: AgriERP FSCM - Dummy Resources v2.pdf — Solution Overview (p.6); Persona – Farm Operations Manager | N22: Manual (needs a mobile shift) | O22: Keep the WO forward-only. | P22: INT-007 | Q22: Not Run
A23: DR-18 | B23: A dummy resource saves without any machine or implement | C23: New | D23: Validation | E23: Admin / Manager | F23: Web | G23: P2 | H23: Functional / Positive | I23: Logged in to the Farm Web App as Admin / Manager (VBS tenant, QA env). Work Orders → Create New Work Order (Planned) is open with Farm, Operation and Plot set — Add Resources stays inert until all three are set. | J23: 1. Add a dummy resource (DR-01). 2. Add no asset. 3. Submit → Save. | K23: Machine Operator (DM001); no asset | L23: The WO saves ("Work Order WO-XXXXX | <name> Saved Successfully"); no asset is required. | M23: AgriERP FSCM - Dummy Resources v2.pdf — Validation Rules → Mandatory Fields (p.26) — machine and implement attachment is optional | N23: ✅ Verified manually 2026-09-30 (WO-1393) | P23: VAL-001 | Q23: Pass
A24: DR-19 | B24: Select Resources shows the dummy resource headcount notice | C24: New | D24: Selecting dummy resources | E24: Admin / Manager | F24: Web | G24: P3 | H24: UI | I24: Logged in to the Farm Web App as Admin / Manager (VBS tenant, QA env). Work Orders → Create New Work Order (Planned) is open with Farm, Operation and Plot set — Add Resources stays inert until all three are set. A dummy resource has been added to the WO. | J24: 1. Look under the Select Resources grid. | K24: — | L24: The notice "Dummy resources stand in for unnamed labour and carry a headcount instead of a person…" is shown. | M24: AgriERP FSCM - Dummy Resources v2.pdf — Figure 1 (p.7) | N24: ❌ Expected failure — FINDINGS #49 (notice not rendered) | O24: Split out of DR-05 on 2026-09-30. | P24: — | Q24: Fail
A25: DRM-01 | B25: Plot card swipe menus | C25: Existing | D25: Setting up the job | E25: Supervisor / Machine Operator | F25: Mobile | G25: P2 | H25: UI | I25: Logged in to the Farm Mobile App as a Supervisor or Machine Operator (VBS tenant, QA env). A Planned WO with at least one plot is assigned to the user; the operation has a dummy resource register. | J25: 1. Open the WO on the Work Order Detail screen. 2. Swipe a plot card right. 3. Swipe the same card left. 4. Repeat on a plot that already has a shift. | K25: — | L25: Swipe right: Add / Update Dummy Resource, Add Resources. Swipe left: Start Job, Edit, Resume, Pause. Available on every plot, whether or not a shift has run. | M25: AgriERP FSCM - Dummy Resources v2.pdf — Figures 3–4 (p.9–10) | N25: Manual (Farm Mobile App) | P25: — | Q25: Not Run
A26: DRM-02 | B26: Dummy Resources empty state | C26: Existing | D26: Setting up the job | E26: Supervisor / Machine Operator | F26: Mobile | G26: P3 | H26: UI | I26: Logged in to the Farm Mobile App as a Supervisor or Machine Operator (VBS tenant, QA env). A Planned WO with at least one plot is assigned to the user; the operation has a dummy resource register. The plot has no dummy resource logs. | J26: 1. Swipe the plot card right → Add / Update Dummy Resource. | K26: — | L26: "No dummy resource logs on this plot yet — tap + to add one."; Total Hours Logged: 0h; Resource 0h + Machine / Implement 0h. | M26: AgriERP FSCM - Dummy Resources v2.pdf — Figure 5 (p.11) | N26: Manual (Farm Mobile App) | P26: — | Q26: Not Run
A27: DRM-03 | B27: Add Dummy Resource lists the dummy register only; multi-select | C27: Existing | D27: Setting up the job | E27: Supervisor / Machine Operator | F27: Mobile | G27: P2 | H27: Functional | I27: Logged in to the Farm Mobile App as a Supervisor or Machine Operator (VBS tenant, QA env). A Planned WO with at least one plot is assigned to the user; the operation has a dummy resource register. | J27: 1. Swipe right → Add / Update Dummy Resource → '+'. 2. Check the list for named app users. 3. Tick two dummy resources. | K27: Machine Operator (DM001), Irrigator (DM002) | L27: Only the operation's dummy resources are listed (no named users); more than one can be ticked; Done becomes active once a row is ticked. | M27: AgriERP FSCM - Dummy Resources v2.pdf — Figures 7–8 (p.13–14) | N27: Manual (Farm Mobile App) | P27: — | Q27: Not Run
A28: DRM-04 | B28: No Of Resources is mandatory, integer > 0 | C28: Existing | D28: Setting up the job | E28: Supervisor / Machine Operator | F28: Mobile | G28: P1 | H28: Negative | I28: Logged in to the Farm Mobile App as a Supervisor or Machine Operator (VBS tenant, QA env). A Planned WO with at least one plot is assigned to the user; the operation has a dummy resource register. Two dummy resources ticked in Add Dummy Resource. | J28: 1. Tap Done. 2. Leave one No Of Resources field empty and try to continue. 3. Enter 0 and try again. 4. Enter 2 in both. | K28: Empty, 0, then 2 | L28: One mandatory No Of Resources field per selected resource; empty or 0 blocks progress; a positive integer lets the flow continue. | M28: AgriERP FSCM - Dummy Resources v2.pdf — Figure 9 (p.15); Validation Rules – Mandatory Fields | N28: ✅ Automated (API) — dummy-shifts-api.spec.ts; screens manual | P28: VAL-001 | Q28: Pass
A29: DRM-05 | B29: Select Asset per resource; Add Machine / Add Dummy Machine sheet | C29: Existing | D29: Setting up the job | E29: Supervisor / Machine Operator | F29: Mobile | G29: P2 | H29: Functional | I29: Logged in to the Farm Mobile App as a Supervisor or Machine Operator (VBS tenant, QA env). A Planned WO with at least one plot is assigned to the user; the operation has a dummy resource register. No Of Resources entered for the selected dummy resources. | J29: 1. On Select Asset, open a resource row. 2. Choose to attach a machine. 3. Choose to attach an implement. 4. Select a machine, tick it and tap Done. | K29: Dummy machine and actual machine available | L29: Add Machine / Add Dummy Machine sheet appears only when dummy assets of that kind exist; implements (no dummy assets today) open the selection page directly; chosen machine is listed against the resource. Either register usable by dummy or named resources. | M29: AgriERP FSCM - Dummy Resources v2.pdf — Figures 10–12 (p.16–18); Dummy Asset Register | N29: Manual (Farm Mobile App) | O29: API check: GET /api/DummyShift/DummyAssetRegister/{assetType} | P29: BIND-004, BIND-009, VAL-006, VAL-007, VAL-008 | Q29: Not Run
A30: DRM-06 | B30: Summary before Start Job | C30: Existing | D30: Setting up the job | E30: Supervisor / Machine Operator | F30: Mobile | G30: P2 | H30: Functional | I30: Logged in to the Farm Mobile App as a Supervisor or Machine Operator (VBS tenant, QA env). A Planned WO with at least one plot is assigned to the user; the operation has a dummy resource register. Dummy resources, headcount and assets selected. | J30: 1. Proceed to the Summary screen. | K30: 2 × Machine Operator (DM001) + machine | L30: Summary shows the plot, dummy resources with headcount, attached assets, and Estimated Hours derived from the headcount. | M30: AgriERP FSCM - Dummy Resources v2.pdf — Figure 13 (p.19) | N30: Manual (Farm Mobile App) | O30: API check: POST /api/DummyShift/Preview | P30: — | Q30: Not Run
A31: DRM-07 | B31: Start Job creates Shift 1 and writes machine bindings | C31: Existing | D31: Starting & resuming (In Progress) | E31: Supervisor / Machine Operator | F31: Mobile | G31: P1 | H31: Functional | I31: Logged in to the Farm Mobile App as a Supervisor or Machine Operator (VBS tenant, QA env). A Planned WO with at least one plot is assigned to the user; the operation has a dummy resource register. Summary reviewed; plot in To Do. | J31: 1. Tap Start Job at 02:00 PM. 2. Check the plot card status. 3. Open Add / Update Dummy Resource. | K31: Start 02:00 PM; Standard Hours 2; No Of Resources 1; actual machine | L31: Shift 1 is created; plot goes In Progress; 2 h logged (1 × 2); machine bound 02:00 PM – 04:00 PM. | M31: AgriERP FSCM - Dummy Resources v2.pdf — Figure 14 (p.20); Machine Binding & Shift Window | N31: ✅ Automated (API) — dummy-shifts-api.spec.ts; screens manual | O31: ⚠ Figure 14 still says 'until Pause or Stop'; the revised Important Point no longer states post-Pause/Stop status. Confirm with PO. · API check: POST /api/DummyShift | P31: BIND-001 | Q31: Pass
A32: DRM-08 | B32: Hours = No. of Resources × Standard Hours; machine logs same hours | C32: Existing | D32: Hours & machine binding | E32: Supervisor / Machine Operator | F32: Mobile | G32: P1 | H32: Functional | I32: Logged in to the Farm Mobile App as a Supervisor or Machine Operator. An In Progress WO (`pnpm seed:hourlog`) has at least one logged dummy resource shift on a plot. | J32: 1. Open Add / Update Dummy Resource on the plot. 2. Read hours per resource, machine hours and Total Hours Logged. 3. Try to edit the hours directly. | K32: 2 res × 2 h + 1 res × 2 h, each with a machine on the first | L32: Hours are read-only and equal headcount × standard hours; the attached machine logs the same hours; plot total = resource + machine hours (Figure 6: 6 h resource + 4 h machine = 10 h). | M32: AgriERP FSCM - Dummy Resources v2.pdf — Figure 6 (p.12); Hour Calculation | N32: ✅ Automated (API) — dummy-shifts-api.spec.ts; screens manual | O32: API check: POST /api/DummyShift/Preview; GET /api/DummyShift/PlotSummary/{workOrderId} | P32: VAL-012, VAL-013, VAL-014 | Q32: Pass
A33: DRM-09 | B33: Machine bound in the shift window cannot be selected | C33: Existing | D33: Hours & machine binding | E33: Supervisor / Machine Operator | F33: Mobile | G33: P1 | H33: Negative | I33: Logged in to the Farm Mobile App as a Supervisor or Machine Operator (VBS tenant, QA env). A Planned WO with at least one plot is assigned to the user; the operation has a dummy resource register. Machine M1 is bound to another resource 02:00–04:00 PM. | J33: 1. Start a shift whose window overlaps 02:00–04:00 PM. 2. On Select Machine, find M1. 3. Tap M1. | K33: M1 bound to Machine Operator (DM001) 02:00–04:00 PM | L33: M1 is greyed out with a Bound tag and "Already bound to <resource> · <start> – <end>"; tapping shows "<Machine> is already bound to <resource> from <start> to <end>." | M33: AgriERP FSCM - Dummy Resources v2.pdf — Figures 15–16 (p.21–22); Machine Binding Validation | N33: ✅ Automated (API) — dummy-shifts-api.spec.ts; screens manual | O33: API check: POST /api/DummyShift/MachineAvailability | P33: BIND-002, BIND-003, BIND-010, VAL-002 | Q33: Pass
A34: DRM-10 | B34: Resume Job appends a new shift to the plot | C34: Updated | D34: Starting & resuming (In Progress) | E34: Supervisor / Machine Operator | F34: Mobile | G34: P1 | H34: Functional / Regression | I34: Logged in to the Farm Mobile App as a Supervisor or Machine Operator (VBS tenant, QA env). A Planned WO in In Progress status (seed with `pnpm seed:hourlog`, which creates the WO and sets it In Progress) has Shift 1 logged on one plot (plot card shows In Progress). Keep the WO forward-only: never revert it to To Do or delete it. | J34: 1. Open the In Progress WO on the Work Order Detail screen (plot shows Shift 1). 2. Swipe the plot card left → Resume. 3. Swipe right → Add / Update Dummy Resource; add a dummy resource, enter No Of Resources, attach a machine, tap Done. 4. Review the Summary and tap Start Job. 5. Repeat steps 2–4 once more. 6. Swipe right → Add / Update Dummy Resource and review the shift list. | K34: Machine Operator (DM001); No Of Resources: 2 | L34: Each Resume runs the same Start Job flow and appends one new shift (Shift 2, then Shift 3). Shift 1 remains listed; no shift is replaced. | M34: AgriERP FSCM - Dummy Resources v2.pdf — Important Point – Resume Job and Shifts (p.22) | N34: ✅ Automated (API) — dummy-shifts-api.spec.ts; screens manual | O34: PSD was: 'appends a second shift'; now: 'appends a new shift'. · API check: POST /api/DummyShift/Resume | P34: — | Q34: Pass
A35: DRM-15 | B35: Plot remains In Progress once the job is started | C35: New | D35: Starting & resuming (In Progress) | E35: Supervisor / Machine Operator | F35: Mobile | G35: P1 | H35: Functional / Regression | I35: Logged in to the Farm Mobile App as a Supervisor or Machine Operator (VBS tenant, QA env). A Planned WO in In Progress status (seed with `pnpm seed:hourlog`, which creates the WO and sets it In Progress) has Shift 1 logged on one plot (plot card shows In Progress). Keep the WO forward-only: never revert it to To Do or delete it. | J35: 1. Open the In Progress WO on the Work Order Detail screen; note the plot card status (Shift 1 logged). 2. Swipe the plot card left → Resume; complete the dummy resource flow and tap Start Job (Shift 2). 3. Note the plot card status. 4. Swipe left → Resume again; complete the flow and tap Start Job (Shift 3). 5. Note the plot card status again. | K35: Irrigator (DM002); No Of Resources: 1 | L35: Plot card reads In Progress before Resume (step 1) and stays In Progress after each Resume (steps 3 and 5). It never returns to To Do between shifts. | M35: AgriERP FSCM - Dummy Resources v2.pdf — Important Point – Resume Job and Shifts (p.22) | N35: ✅ Automated (API, WO status) — dummy-shifts-api.spec.ts; screens manual | O35: PSD dropped 'only Pause or Stop returns it to To Do'. | P35: — | Q35: Pass
A36: DRM-16 | B36: Each new shift's hours add to the plot total | C36: New | D36: Starting & resuming (In Progress) | E36: Supervisor / Machine Operator | F36: Mobile | G36: P2 | H36: Functional | I36: Logged in to the Farm Mobile App as a Supervisor or Machine Operator (VBS tenant, QA env). A Planned WO in In Progress status (seed with `pnpm seed:hourlog`, which creates the WO and sets it In Progress) has Shift 1 logged on one plot (plot card shows In Progress). Keep the WO forward-only: never revert it to To Do or delete it. Shift 1 was logged with 2 dummy resources; standard hours = 2 h. | J36: 1. Confirm Shift 1 on the In Progress plot has 2 dummy resources. 2. Note Total Hours Logged in Add / Update Dummy Resource. 3. Swipe left → Resume; add 1 dummy resource and tap Start Job (Shift 2). 4. Reopen Add / Update Dummy Resource and read Total Hours Logged and each shift's hours. | K36: Shift 1: 2 × 2 h; Shift 2: 1 × 2 h | L36: Shift 1 logs 4 h, Shift 2 logs 2 h; Total Hours Logged shows 6 h resource (plus machine hours). Shift 1 still shows 4 h. | M36: AgriERP FSCM - Dummy Resources v2.pdf — Important Point – Resume Job and Shifts (p.22) | N36: ✅ Automated (API) — dummy-shifts-api.spec.ts; screens manual | O36: API check: GET /api/DummyShift/PlotSummary/{workOrderId} | P36: — | Q36: Pass
A37: DRM-17 | B37: Multiple shifts per day keep their own resources, headcount, machines and window | C37: New | D37: Starting & resuming (In Progress) | E37: Supervisor / Machine Operator | F37: Mobile | G37: P2 | H37: Functional | I37: Logged in to the Farm Mobile App as a Supervisor or Machine Operator (VBS tenant, QA env). A Planned WO in In Progress status (seed with `pnpm seed:hourlog`, which creates the WO and sets it In Progress) has Shift 1 logged on one plot (plot card shows In Progress). Keep the WO forward-only: never revert it to To Do or delete it. Shift 1 uses dummy resource A × 2 with machine M1; dummy resource B and machine M2 are available. | J37: 1. Confirm Shift 1 on the In Progress plot uses dummy resource A, No Of Resources 2, machine M1. 2. Swipe left → Resume; add dummy resource B, No Of Resources 3, machine M2; tap Start Job (Shift 2). 3. Open Add / Update Dummy Resource and compare both shifts. | K37: A: Machine Operator (DM001); B: Irrigator (DM002); M1/M2: two unbound machines | L37: Both shifts listed on the same plot and day. Shift 1: A × 2, M1, own window. Shift 2: B × 3, M2, own window. Shift 1 unchanged. | M37: AgriERP FSCM - Dummy Resources v2.pdf — Important Point – Resume Job and Shifts (p.22) | N37: ✅ Automated (API) — dummy-shifts-api.spec.ts; screens manual | O37: API check: GET /api/DummyShift/Line/{workOrderLineId} | P37: — | Q37: Pass
A38: DRM-11 | B38: Raising headcount extends hours and binding window; blocked on conflict | C38: Existing | D38: Hours & machine binding | E38: Supervisor / Machine Operator | F38: Mobile | G38: P1 | H38: Functional / Negative | I38: Logged in to the Farm Mobile App as a Supervisor or Machine Operator. An In Progress WO (`pnpm seed:hourlog`) has at least one logged dummy resource shift on a plot. The shift has an actual machine; that machine was used by an actual resource on the same WO right after the shift window. | J38: 1. Tap the pencil on the shift. 2. Raise No Of Resources by 1 on a machine with no conflict; save. 3. On the conflicting shift, raise No Of Resources so the window overlaps the actual resource's use. | K38: No Of Resources 1 → 2 | L38: Step 2: hours and binding end extend. Step 3: change blocked, Save stays disabled until the headcount is reduced or the machine is freed. | M38: AgriERP FSCM - Dummy Resources v2.pdf — Headcount Update Validation (p.22) | N38: ✅ Automated (API) — dummy-shifts-api.spec.ts; screens manual | O38: API check: PUT /api/DummyShift/Resource/{shiftResourceId}/Headcount | P38: BIND-005, BIND-006, BIND-007, BIND-008, VAL-003 | Q38: Pass
A39: DRM-12 | B39: Correct or delete a shift | C39: Existing | D39: Corrections, availability & audit | E39: Supervisor / Machine Operator | F39: Mobile | G39: P2 | H39: Functional | I39: Logged in to the Farm Mobile App as a Supervisor or Machine Operator. An In Progress WO (`pnpm seed:hourlog`) has at least one logged dummy resource shift on a plot. | J39: 1. Tap the pencil; change No Of Resources. 2. Remove one resource from a multi-resource shift. 3. Tap the bin on a shift. 4. Remove the last resource of another shift. 5. On a posted, completed WO, try to delete a shift. | K39: — | L39: Hours and window recalculate; Remove takes the resource off; bin deletes the shift and its hours/bindings from the total; removing the last resource deletes the shift; deletion not allowed once posted and the WO is completed. | M39: AgriERP FSCM - Dummy Resources v2.pdf — Important Point – Correcting and Deleting a Shift (p.22–23) | N39: ✅ Automated (API) — dummy-shifts-api.spec.ts; screens manual | O39: API check: DELETE /api/DummyShift/{shiftId}, /Resource/{shiftResourceId}, /Asset/{shiftAssetId} | P39: VAL-009, VAL-010, VAL-011 | Q39: Pass
A40: DRM-13 | B40: Named resource on a running job is unavailable; dummy unrestricted | C40: Existing | D40: Corrections, availability & audit | E40: Supervisor / Machine Operator | F40: Mobile | G40: P2 | H40: Negative | I40: Logged in to the Farm Mobile App as a Supervisor or Machine Operator (VBS tenant, QA env). A Planned WO with at least one plot is assigned to the user; the operation has a dummy resource register. A named resource is working on a running job on another plot. | J40: 1. Add Resources for a new shift; find the busy named resource. 2. Tap it. 3. Add a dummy resource that is on a running job. | K40: Named resource busy on another plot | L40: Named row shows "Already working on <plot>" and tapping raises an error; dummy resource can be selected. | M40: AgriERP FSCM - Dummy Resources v2.pdf — Named Resource Availability Validation | N40: Partial: API covers dummy availability; named half manual — dummy-shifts-api.spec.ts; screens manual | O40: API check: POST /api/DummyShift/ResourceAvailability | P40: VAL-004, VAL-005 | Q40: Pass
A41: DRM-14 | B41: Audit trail for shifts and corrections | C41: Existing | D41: Corrections, availability & audit | E41: Supervisor / Machine Operator | F41: Mobile | G41: P2 | H41: Functional | I41: Logged in to the Farm Mobile App as a Supervisor or Machine Operator. An In Progress WO (`pnpm seed:hourlog`) has at least one logged dummy resource shift on a plot. | J41: 1. Start a shift, then correct its headcount. 2. Open notifications. 3. Open View All Logs. | K41: — | L41: Each shift and correction records user, timestamp, source (Web/Mobile) and device, and is shown in notifications and View All Logs. | M41: AgriERP FSCM - Dummy Resources v2.pdf — Dummy Resource Audit Trail Logs (p.23) | N41: Partial (API): ❌ detach not logged (#50), corrections lack device (#53) — dummy-shifts-api.spec.ts; screens manual | O41: API check: GET /api/DummyShift/{shiftId}/Logs, /WorkOrder/{workOrderId}/Logs | P41: AUD-001, AUD-002, AUD-003, AUD-004, AUD-005 | Q41: Fail
...

Sheet Summary
A1: Summary
A3: By change | B3: Count
A4: New | B4: =COUNTIF('Test Cases'!$C$6:$C$47,"New") -> 19
A5: Updated | B5: =COUNTIF('Test Cases'!$C$6:$C$47,"Updated") -> 4
A6: Existing | B6: =COUNTIF('Test Cases'!$C$6:$C$47,"Existing") -> 19
A7: Total | B7: =SUM(B4:B6) -> 42
A9: By platform | B9: Count
A10: Web | B10: =COUNTIF('Test Cases'!$F$6:$F$47,"Web") -> 22
A11: Mobile | B11: =COUNTIF('Test Cases'!$F$6:$F$47,"Mobile") -> 19
A12: Web / D365 | B12: =COUNTIF('Test Cases'!$F$6:$F$47,"Web / D365") -> 1
A13: Total | B13: =SUM(B10:B12) -> 42
A15: By priority | B15: Count
A16: P1 | B16: =COUNTIF('Test Cases'!$G$6:$G$47,"P1") -> 17
A17: P2 | B17: =COUNTIF('Test Cases'!$G$6:$G$47,"P2") -> 18
A18: P3 | B18: =COUNTIF('Test Cases'!$G$6:$G$47,"P3") -> 7
A19: Total | B19: =SUM(B16:B18) -> 42
A21: By result | B21: Count
A22: Pass | B22: =COUNTIF('Test Cases'!$Q$6:$Q$47,"Pass") -> 19
A23: Fail | B23: =COUNTIF('Test Cases'!$Q$6:$Q$47,"Fail") -> 3
A24: Blocked | B24: =COUNTIF('Test Cases'!$Q$6:$Q$47,"Blocked") -> 2
A25: Not Run | B25: =COUNTIF('Test Cases'!$Q$6:$Q$47,"Not Run") -> 18
A26: Total | B26: =SUM(B22:B25) -> 42
A28: Open question: the revised PSD no longer states the plot status after Pause or Stop (Figure 14 still says 'until Pause or Stop'). Confirm with the PO before adding a case.

Sheet ADO 26191
A1: ADO #26191 developer note (Mohsin Aqee, 2026-09-29) → test coverage
A2: Source: resources/work-items/26191-dummy-resource-v2.md
A4: Kind | B4: Item | C4: Our case(s) | D4: Coverage
A5: Implemented | B5: Shift per plot on Start/Resume Job (crews, headcount, machines, window); many shifts per plot | C5: DRM-07, DRM-10, DRM-15, DRM-16, DRM-17 | D5: Automated (API)
A6: Implemented | B6: Server calculates hours = headcount × standard hours | C6: DRM-08 | D6: Automated (API)
A7: Implemented | B7: Machines booked for the shift window, no double use | C7: DRM-09, DRM-11 | D7: Automated (API)
A8: Implemented | B8: Mobile corrections: headcount, remove crew, delete shift, attach/detach machine | C8: DRM-11, DRM-12 | D8: Automated (API)
A9: Implemented | B9: Web API api/DummyShift/* (plot cards, shift list, edit, delete, history, posting checks) | C9: DRM-04..17, DR-08 | D9: Automated: dummy-shifts-api.spec.ts (FINDINGS #50–#53)
A10: Implemented | B10: Full history log | C10: DRM-14 | D10: Automated (API)
A11: Implemented | B11: Shifts sync back to Firebase | C11: DRM-10 (mobile view) | D11: Manual
A12: Impact 1 | B12: Spent Hours (GET api/WorkOrder/HourLogs) | C12: DRI-01 | D12: Partial
A13: Impact 2 | B13: WorkOrderHourLogs table: create, edit, void, approve | C13: DRI-02 | D13: Partial
A14: Impact 3 | B14: WO sync to mobile (ComAX) | C14: DRI-03 | D14: Manual
A15: Impact 4 | B15: Start Job for named resources (ComAX) | C15: DRI-04 | D15: Manual
... A17: Impact 6 | B17: Old dummy resources (Enh 25942) | C17: DRI-06 | D17: Manual

Sheet Client Mapping
A1: Client sheet → this suite (non-mobile tabs only; the client's 'Mobile - Dummy Resource' tab was skipped)
A2: Client file: resources/Vann Brothers test cases/Vann Brothers test cases/AgriERP_Dummy_Resource_Test_Cases.xlsx
A4: Client TC | B4: Client tab | C4: Client scenario | D4: Our case(s) | E4: Coverage | F4: Note
A5: WEB-001 | B5: Web - Resource Selection | C5: "+" icon on Select Resources opens the dropdown | D5: DR-02 | E5: Covered
A6: WEB-002 | B6: Web - Resource Selection | C6: Selecting "Add Dummy Resource" opens the dummy-filtered selection page | D6: DR-03 | E6: Covered
A7: WEB-003 | B7: Web - Resource Selection | C7: Dummy Resource Yes/No toggle is removed from the selection page | D7: DR-03, DR-04 | E7: Covered | F7: Both register pages assert no toggle.
A8: WEB-004 | B8: Web - Resource Selection | C8: Resource Group filter narrows the dummy list | D8: DR-11 | E8: Added
A9: WEB-005 | B9: Web - Resource Selection | C9: Search by Resource Name filter works on the dummy list | D9: DR-12 | E9: Added
A10: WEB-006 | B10: Web - Resource Selection | C10: Search by Company Name filter works on the dummy list | D10: DR-13 | E10: Added
A11: WEB-007 | B11: Web - Resource Selection | C11: Reset clears all applied filters | D11: DR-14 | E11: Added | F11: Fails live: Reset switches to the named register (FINDINGS #48).
A12: WEB-008 | B12: Web - Resource Selection | C12: Resources already on the work order show the yellow "Dummy Resource" chip | D12: DR-05 | E12: Covered | F12: Chip verified live 2026-09-30.
A13: WEB-009 | B13: Web - Resource Selection | C13: "Add Resource" opens the named/actual resource register, not the dummy one | D13: DR-04 | E13: Covered
A14: WEB-010 | B14: Web - Resource Selection | C14: Register cannot be changed mid-selection (dummy vs. named) | D14: DR-03, DR-04 | E14: Covered | F14: Same check as client WEB-003 (no in-page register switch).
A15: WEB-011 | B15: Web - Resource Selection | C15: Multiple dummy resources can be selected and saved in one pass | D15: DR-15 | E15: Added
A16: WEB-012 | B16: Web - Resource Selection | C16: Dummy resources are maintained as flagged master data in Resource Management | D16: DR-16 | E16: Added
A17: BIND-001 | B17: Machine Binding & Window | C17: Machine binding window is derived from shift start time and planned hours | D17: DRM-07 | E17: Covered
A18: BIND-002 | B18: Machine Binding & Window | C18: A machine bound for any part of the requested window is greyed out and tagged Bound | D18: DRM-09 | E18: Covered | F18: Client adds the shift-window banner text from the mock; mobile, not added.
A19: BIND-003 | B19: Machine Binding & Window | C19: Selecting a Bound machine is blocked with an inline error | D19: DRM-09 | E19: Covered
A20: BIND-004 | B20: Machine Binding & Window | C20: A machine with no conflicting window can be selected normally | D20: DRM-05 | E20: Covered
A21: BIND-005 | B21: Machine Binding & Window | C21: Raising No. of Resources on an existing shift extends hours and the binding window end time | D21: DRM-11 | E21: Covered
A22: BIND-006 | B22: Machine Binding & Window | C22: Headcount increase re-validates the machine only over the newly claimed (extra) time | D22: DRM-11 | E22: Partial | F22: Re-check limited to the extra time isn't asserted separately. Mobile, not added.
A23: BIND-007 | B23: Machine Binding & Window | C23: Headcount increase is blocked when the machine was used by an actual (named) resource during the extra time | D23: DRM-11 | E23: Covered
A24: BIND-008 | B24: Machine Binding & Window | C24: Headcount increase succeeds when the machine is free during the extra time | D24: DRM-11 | E24: Covered
A25: BIND-009 | B25: Machine Binding & Window | C25: Both dummy and named resources may work with either an actual or a dummy machine | D25: DRM-05 | E25: Covered
A26: BIND-010 | B26: Machine Binding & Window | C26: An actual machine is unavailable to any other crew for the whole bound window | D26: DRM-09 | E26: Partial | F26: DRM-09 doesn't cover the machine being bound on a different WO. Mobile, not added.
A27: VAL-001 | B27: Validation Rules | C27: No. of Resources is mandatory and must be greater than zero (Web & Mobile) | D27: DRM-04, DR-18 | E27: Covered | F27: The quantity is a mobile field: enforced at Start Job (DRM-04, API). 'Attachment optional' clause: DR-18. DR-06 retired.
A28: VAL-002 | B28: Validation Rules | C28: Machine already bound for any part of a shift window cannot be selected | D28: DRM-09 | E28: Covered
A29: VAL-003 | B29: Validation Rules | C29: Headcount increase is re-validated and blocked on conflict with an actual resource | D29: DRM-11 | E29: Covered
A30: VAL-004 | B30: Validation Rules | C30: A named resource already on a running job cannot be selected again | D30: DR-09, DRM-13 | E30: Covered
A31: VAL-005 | B31: Validation Rules | C31: Dummy resources are never blocked by a running job | D31: DR-09, DRM-13 | E31: Covered
A32: VAL-006 | B32: Validation Rules | C32: Add Machine / Add Dummy Machine choice is shown only when the register holds a dummy asset of that kind | D32: DRM-05 | E32: Covered
A33: VAL-007 | B33: Validation Rules | C33: Selection page opens directly when the register holds no dummy asset of that kind | D33: DRM-05 | E33: Covered
A34: VAL-008 | B34: Validation Rules | C34: Both dummy and named resources may select from either asset register | D34: DRM-05 | E34: Covered
A35: VAL-009 | B35: Validation Rules | C35: Deleting a shift removes its hours and machine bindings from the plot total | D35: DRM-12 | E35: Covered
A36: VAL-010 | B36: Validation Rules | C36: Removing the last resource of a shift deletes the shift | D36: DRM-12 | E36: Covered
A37: VAL-011 | B37: Validation Rules | C37: Shift/resource deletion is blocked once the work order is completed and hours are posted | D37: DRM-12 | E37: Covered
A38: VAL-012 | B38: Validation Rules | C38: Hours logged equal No. of Resources × Standard Hours and are read-only | D38: DRM-08 | E38: Covered
A39: VAL-013 | B39: Validation Rules | C39: Machine/implement hours equal the hours of the resource they are attached to | D39: DRM-08 | E39: Covered
... A45: INT-005 | B45: Integrations | C45: System-generated dummy resource logs appear on Hour Log Adjustment with headcount and standard hours | D45: DR-07 | E45: Covered
A46: INT-006 | B46: Integrations | C46: Dummy resource hours are visible with source, device, and user on Web resource list, Spent Hours, and WO logs | D46: DR-07 | E46: Extended | F46: DR-07 now also checks the work order logs.
...
