Workbook

Sheet Cover
B2: AgriERP / AgriFarm - Vann Brothers Regression Test Suite (Web + iOS)
B5: Client / Product | C5: Vann Brothers - AgriERP / AgriFarm (Farm App)
B6: Environment under test | C6: Vann Brothers - QA | https://agrierp-vann-qa.folio3.site
B7: Platforms in scope | C7: Web application (Chromium based browser) and native iOS app (iPhone)
B8: Integrated systems | C8: Microsoft Dynamics 365 F&O (projects, tasks, resources, assets, materials, inventory, posting)
B9: Prepared by | C9: QA - Folio3
B10: Prepared on | C10: 26-Aug-2026
B11: Suite type | C11: Full regression - execute per release candidate before UAT sign-off
B12: Scope | C12: Maps, Planning, Work Orders (Planned / Inspection / Observations / Harvest), Harvest Central, Template Management, Communication Center, Settings, Users & Roles, Sync Console & D365 integration, iOS offline & sync, attachments & PDF export, weather & location tracking, cross-cutting NFRs.
B13: Out of scope | C13: Android app, D365 F&O internal screens, AgriERP Inventory app, load/stress testing beyond the listed performance checks.
B14: Objective | C14: Establish that every documented flow across web and iOS still behaves correctly after a release, that data reconciles between the two platforms and D365, and that previously closed defects have not regressed.
B16: Estimation basis
B17: • Estimates are DELIBERATELY CONSERVATIVE, not optimal. They assume a single manual tester on a prepared environment, working at a sustainable pace.
B18: • Each estimate covers: reading the case, setting up the prerequisite data, executing every step, verifying the expected result, and recording the outcome.
B19: • Cross-platform cases (Web + iOS) include the time to perform the action on one platform and verify it on the other, including the sync wait.
B20: • Integration and D365 cases include the wait for the sync/posting batch job to run before the result can be verified.
B21: • Estimates exclude defect investigation, re-testing after a fix, and environment downtime. Budget a further 25-30% of the total for those.
B22: • A productive day is assumed to be 6 hours of actual execution, not 8.
B24: How to use this workbook
B25: 1. One tab per module. Execute top to bottom; each row is one test case.
B26: 2. Fill only the three yellow columns: Status, Actual Result and Comments. Everything else is a read-only test asset.
B27: 3. Status values: Not Run / Pass / Fail / Blocked / N-A (dropdown provided). Pass, Fail and Blocked are colour-coded automatically.
B28: 4. The Platform column states where the case runs: Web, iOS, or Web + iOS (execute on one and verify on the other).
... B34: Legend
B35: Header / test asset | C35: Read-only - do not edit
B36: Tester input | C36: Status, Actual Result, Comments
B37: Calculated | C37: Formula-driven - do not overwrite

Sheet Health Summary
B2: Application Health Summary - AgriERP / AgriFarm (Web + iOS)
B3: Every figure below is formula-driven from the module tabs. Update the Status column on each tab and this sheet recalculates.
B5: Module | C5: Cases | D5: P1 | E5: P2 | F5: P3 | G5: Web | H5: iOS | I5: Both | J5: Est. (min) | K5: Est. (hrs) | L5: Pass | M5: Fail | N5: Blocked | O5: Not Run | P5: Executed % | Q5: Pass %
B6: Global & Navigation | C6: =COUNTA('01 Global & Navigation'!$A$3:$A$62) -> 60 | D6: =COUNTIF('01 Global & Navigation'!$I$3:$I$62,"P1") -> 31 | E6: =COUNTIF('01 Global & Navigation'!$I$3:$I$62,"P2") -> 26 | F6: =COUNTIF('01 Global & Navigation'!$I$3:$I$62,"P3") -> 3 | G6: =COUNTIF('01 Global & Navigation'!$D$3:$D$62,"Web") -> 44 | H6: =COUNTIF('01 Global & Navigation'!$D$3:$D$62,"iOS") -> 15 | I6: =COUNTIF('01 Global & Navigation'!$D$3:$D$62,"Web + iOS") -> 1 | J6: =SUM('01 Global & Navigation'!$K$3:$K$62) -> 1061 | K6: =J6/60 -> 17.683333 | L6: =COUNTIF('01 Global & Navigation'!$L$3:$L$62,"Pass") -> 0 | M6: =COUNTIF('01 Global & Navigation'!$L$3:$L$62,"Fail") -> 0 | N6: =COUNTIF('01 Global & Navigation'!$L$3:$L$62,"Blocked") -> 0 | O6: =COUNTIF('01 Global & Navigation'!$L$3:$L$62,"Not Run") -> 60 | P6: =IFERROR((L6+M6+N6)/C6,0) -> 0 | Q6: =IFERROR(L6/(L6+M6+N6),0) -> 0
B7: Maps | C7: =COUNTA('02 Maps'!$A$3:$A$63) -> 61 | D7: =COUNTIF('02 Maps'!$I$3:$I$63,"P1") -> 27 | E7: =COUNTIF('02 Maps'!$I$3:$I$63,"P2") -> 28 | F7: =COUNTIF('02 Maps'!$I$3:$I$63,"P3") -> 6 | G7: =COUNTIF('02 Maps'!$D$3:$D$63,"Web") -> 44 | H7: =COUNTIF('02 Maps'!$D$3:$D$63,"iOS") -> 17 | I7: =COUNTIF('02 Maps'!$D$3:$D$63,"Web + iOS") -> 0 | J7: =SUM('02 Maps'!$K$3:$K$63) -> 1157 | K7: =J7/60 -> 19.283333 | L7: =COUNTIF('02 Maps'!$L$3:$L$63,"Pass") -> 0 | M7: =COUNTIF('02 Maps'!$L$3:$L$63,"Fail") -> 0 | N7: =COUNTIF('02 Maps'!$L$3:$L$63,"Blocked") -> 0 | O7: =COUNTIF('02 Maps'!$L$3:$L$63,"Not Run") -> 61 | P7: =IFERROR((L7+M7+N7)/C7,0) -> 0 | Q7: =IFERROR(L7/(L7+M7+N7),0) -> 0
B8: Planning | C8: =COUNTA('03 Planning'!$A$3:$A$43) -> 41 | D8: =COUNTIF('03 Planning'!$I$3:$I$43,"P1") -> 26 | E8: =COUNTIF('03 Planning'!$I$3:$I$43,"P2") -> 14 | F8: =COUNTIF('03 Planning'!$I$3:$I$43,"P3") -> 1 | G8: =COUNTIF('03 Planning'!$D$3:$D$43,"Web") -> 41 | H8: =COUNTIF('03 Planning'!$D$3:$D$43,"iOS") -> 0 | I8: =COUNTIF('03 Planning'!$D$3:$D$43,"Web + iOS") -> 0 | J8: =SUM('03 Planning'!$K$3:$K$43) -> 828 | K8: =J8/60 -> 13.8 | L8: =COUNTIF('03 Planning'!$L$3:$L$43,"Pass") -> 0 | M8: =COUNTIF('03 Planning'!$L$3:$L$43,"Fail") -> 0 | N8: =COUNTIF('03 Planning'!$L$3:$L$43,"Blocked") -> 0 | O8: =COUNTIF('03 Planning'!$L$3:$L$43,"Not Run") -> 41 | P8: =IFERROR((L8+M8+N8)/C8,0) -> 0 | Q8: =IFERROR(L8/(L8+M8+N8),0) -> 0
B9: Work Orders - Planned | C9: =COUNTA('04 WO - Planned'!$A$3:$A$97) -> 95 | D9: =COUNTIF('04 WO - Planned'!$I$3:$I$97,"P1") -> 66 | E9: =COUNTIF('04 WO - Planned'!$I$3:$I$97,"P2") -> 28 | F9: =COUNTIF('04 WO - Planned'!$I$3:$I$97,"P3") -> 1 | G9: =COUNTIF('04 WO - Planned'!$D$3:$D$97,"Web") -> 77 | H9: =COUNTIF('04 WO - Planned'!$D$3:$D$97,"iOS") -> 13 | I9: =COUNTIF('04 WO - Planned'!$D$3:$D$97,"Web + iOS") -> 5 | J9: =SUM('04 WO - Planned'!$K$3:$K$97) -> 2176 | K9: =J9/60 -> 36.266667 | L9: =COUNTIF('04 WO - Planned'!$L$3:$L$97,"Pass") -> 0 | M9: =COUNTIF('04 WO - Planned'!$L$3:$L$97,"Fail") -> 0 | N9: =COUNTIF('04 WO - Planned'!$L$3:$L$97,"Blocked") -> 0 | O9: =COUNTIF('04 WO - Planned'!$L$3:$L$97,"Not Run") -> 95 | P9: =IFERROR((L9+M9+N9)/C9,0) -> 0 | Q9: =IFERROR(L9/(L9+M9+N9),0) -> 0
B10: Work Orders - Inspection | C10: =COUNTA('05 WO - Inspection'!$A$3:$A$47) -> 45 | D10: =COUNTIF('05 WO - Inspection'!$I$3:$I$47,"P1") -> 35 | E10: =COUNTIF('05 WO - Inspection'!$I$3:$I$47,"P2") -> 10 | F10: =COUNTIF('05 WO - Inspection'!$I$3:$I$47,"P3") -> 0 | G10: =COUNTIF('05 WO - Inspection'!$D$3:$D$47,"Web") -> 20 | H10: =COUNTIF('05 WO - Inspection'!$D$3:$D$47,"iOS") -> 20 | I10: =COUNTIF('05 WO - Inspection'!$D$3:$D$47,"Web + iOS") -> 5 | J10: =SUM('05 WO - Inspection'!$K$3:$K$47) -> 1110 | K10: =J10/60 -> 18.5 | L10: =COUNTIF('05 WO - Inspection'!$L$3:$L$47,"Pass") -> 0 | M10: =COUNTIF('05 WO - Inspection'!$L$3:$L$47,"Fail") -> 0 | N10: =COUNTIF('05 WO - Inspection'!$L$3:$L$47,"Blocked") -> 0 | O10: =COUNTIF('05 WO - Inspection'!$L$3:$L$47,"Not Run") -> 45 | P10: =IFERROR((L10+M10+N10)/C10,0) -> 0 | Q10: =IFERROR(L10/(L10+M10+N10),0) -> 0
B11: Work Orders - Observations | C11: =COUNTA('06 WO - Observations'!$A$3:$A$41) -> 39 | D11: =COUNTIF('06 WO - Observations'!$I$3:$I$41,"P1") -> 30 | E11: =COUNTIF('06 WO - Observations'!$I$3:$I$41,"P2") -> 9 | F11: =COUNTIF('06 WO - Observations'!$I$3:$I$41,"P3") -> 0 | G11: =COUNTIF('06 WO - Observations'!$D$3:$D$41,"Web") -> 13 | H11: =COUNTIF('06 WO - Observations'!$D$3:$D$41,"iOS") -> 22 | I11: =COUNTIF('06 WO - Observations'!$D$3:$D$41,"Web + iOS") -> 4 | J11: =SUM('06 WO - Observations'!$K$3:$K$41) -> 829 | K11: =J11/60 -> 13.816667 | L11: =COUNTIF('06 WO - Observations'!$L$3:$L$41,"Pass") -> 0 | M11: =COUNTIF('06 WO - Observations'!$L$3:$L$41,"Fail") -> 0 | N11: =COUNTIF('06 WO - Observations'!$L$3:$L$41,"Blocked") -> 0 | O11: =COUNTIF('06 WO - Observations'!$L$3:$L$41,"Not Run") -> 39 | P11: =IFERROR((L11+M11+N11)/C11,0) -> 0 | Q11: =IFERROR(L11/(L11+M11+N11),0) -> 0
B12: Work Orders - Harvest | C12: =COUNTA('07 WO - Harvest'!$A$3:$A$30) -> 28 | D12: =COUNTIF('07 WO - Harvest'!$I$3:$I$30,"P1") -> 24 | E12: =COUNTIF('07 WO - Harvest'!$I$3:$I$30,"P2") -> 4 | F12: =COUNTIF('07 WO - Harvest'!$I$3:$I$30,"P3") -> 0 | G12: =COUNTIF('07 WO - Harvest'!$D$3:$D$30,"Web") -> 8 | H12: =COUNTIF('07 WO - Harvest'!$D$3:$D$30,"iOS") -> 19 | I12: =COUNTIF('07 WO - Harvest'!$D$3:$D$30,"Web + iOS") -> 1 | J12: =SUM('07 WO - Harvest'!$K$3:$K$30) -> 755 | K12: =J12/60 -> 12.583333 | L12: =COUNTIF('07 WO - Harvest'!$L$3:$L$30,"Pass") -> 0 | M12: =COUNTIF('07 WO - Harvest'!$L$3:$L$30,"Fail") -> 0 | N12: =COUNTIF('07 WO - Harvest'!$L$3:$L$30,"Blocked") -> 0 | O12: =COUNTIF('07 WO - Harvest'!$L$3:$L$30,"Not Run") -> 28 | P12: =IFERROR((L12+M12+N12)/C12,0) -> 0 | Q12: =IFERROR(L12/(L12+M12+N12),0) -> 0
B13: Harvest Central | C13: =COUNTA('08 Harvest Central'!$A$3:$A$49) -> 47 | D13: =COUNTIF('08 Harvest Central'!$I$3:$I$49,"P1") -> 25 | E13: =COUNTIF('08 Harvest Central'!$I$3:$I$49,"P2") -> 22 | F13: =COUNTIF('08 Harvest Central'!$I$3:$I$49,"P3") -> 0 | G13: =COUNTIF('08 Harvest Central'!$D$3:$D$49,"Web") -> 45 | H13: =COUNTIF('08 Harvest Central'!$D$3:$D$49,"iOS") -> 0 | I13: =COUNTIF('08 Harvest Central'!$D$3:$D$49,"Web + iOS") -> 2 | J13: =SUM('08 Harvest Central'!$K$3:$K$49) -> 957 | K13: =J13/60 -> 15.95 | L13: =COUNTIF('08 Harvest Central'!$L$3:$L$49,"Pass") -> 0 | M13: =COUNTIF('08 Harvest Central'!$L$3:$L$49,"Fail") -> 0 | N13: =COUNTIF('08 Harvest Central'!$L$3:$L$49,"Blocked") -> 0 | O13: =COUNTIF('08 Harvest Central'!$L$3:$L$49,"Not Run") -> 47 | P13: =IFERROR((L13+M13+N13)/C13,0) -> 0 | Q13: =IFERROR(L13/(L13+M13+N13),0) -> 0
B14: Template Management | C14: =COUNTA('09 Template Management'!$A$3:$A$77) -> 75 | D14: =COUNTIF('09 Template Management'!$I$3:$I$77,"P1") -> 37 | E14: =COUNTIF('09 Template Management'!$I$3:$I$77,"P2") -> 36 | F14: =COUNTIF('09 Template Management'!$I$3:$I$77,"P3") -> 2 | G14: =COUNTIF('09 Template Management'!$D$3:$D$77,"Web") -> 73 | H14: =COUNTIF('09 Template Management'!$D$3:$D$77,"iOS") -> 0 | I14: =COUNTIF('09 Template Management'!$D$3:$D$77,"Web + iOS") -> 2 | J14: =SUM('09 Template Management'!$K$3:$K$77) -> 1495 | K14: =J14/60 -> 24.916667 | L14: =COUNTIF('09 Template Management'!$L$3:$L$77,"Pass") -> 0 | M14: =COUNTIF('09 Template Management'!$L$3:$L$77,"Fail") -> 0 | N14: =COUNTIF('09 Template Management'!$L$3:$L$77,"Blocked") -> 0 | O14: =COUNTIF('09 Template Management'!$L$3:$L$77,"Not Run") -> 75 | P14: =IFERROR((L14+M14+N14)/C14,0) -> 0 | Q14: =IFERROR(L14/(L14+M14+N14),0) -> 0
B15: Communication Center | C15: =COUNTA('10 Communication Center'!$A$3:$A$57) -> 55 | D15: =COUNTIF('10 Communication Center'!$I$3:$I$57,"P1") -> 23 | E15: =COUNTIF('10 Communication Center'!$I$3:$I$57,"P2") -> 30 | F15: =COUNTIF('10 Communication Center'!$I$3:$I$57,"P3") -> 2 | G15: =COUNTIF('10 Communication Center'!$D$3:$D$57,"Web") -> 50 | H15: =COUNTIF('10 Communication Center'!$D$3:$D$57,"iOS") -> 1 | I15: =COUNTIF('10 Communication Center'!$D$3:$D$57,"Web + iOS") -> 4 | J15: =SUM('10 Communication Center'!$K$3:$K$57) -> 1204 | K15: =J15/60 -> 20.066667 | L15: =COUNTIF('10 Communication Center'!$L$3:$L$57,"Pass") -> 0 | M15: =COUNTIF('10 Communication Center'!$L$3:$L$57,"Fail") -> 0 | N15: =COUNTIF('10 Communication Center'!$L$3:$L$57,"Blocked") -> 0 | O15: =COUNTIF('10 Communication Center'!$L$3:$L$57,"Not Run") -> 55 | P15: =IFERROR((L15+M15+N15)/C15,0) -> 0 | Q15: =IFERROR(L15/(L15+M15+N15),0) -> 0
B16: Settings | C16: =COUNTA('11 Settings'!$A$3:$A$42) -> 40 | D16: =COUNTIF('11 Settings'!$I$3:$I$42,"P1") -> 18 | E16: =COUNTIF('11 Settings'!$I$3:$I$42,"P2") -> 22 | F16: =COUNTIF('11 Settings'!$I$3:$I$42,"P3") -> 0 | G16: =COUNTIF('11 Settings'!$D$3:$D$42,"Web") -> 38 | H16: =COUNTIF('11 Settings'!$D$3:$D$42,"iOS") -> 0 | I16: =COUNTIF('11 Settings'!$D$3:$D$42,"Web + iOS") -> 2 | J16: =SUM('11 Settings'!$K$3:$K$42) -> 840 | K16: =J16/60 -> 14 | L16: =COUNTIF('11 Settings'!$L$3:$L$42,"Pass") -> 0 | M16: =COUNTIF('11 Settings'!$L$3:$L$42,"Fail") -> 0 | N16: =COUNTIF('11 Settings'!$L$3:$L$42,"Blocked") -> 0 | O16: =COUNTIF('11 Settings'!$L$3:$L$42,"Not Run") -> 40 | P16: =IFERROR((L16+M16+N16)/C16,0) -> 0 | Q16: =IFERROR(L16/(L16+M16+N16),0) -> 0
B17: Users, Roles & Permissions | C17: =COUNTA('12 Users, Roles & Perms'!$A$3:$A$53) -> 51 | D17: =COUNTIF('12 Users, Roles & Perms'!$I$3:$I$53,"P1") -> 37 | E17: =COUNTIF('12 Users, Roles & Perms'!$I$3:$I$53,"P2") -> 13 | F17: =COUNTIF('12 Users, Roles & Perms'!$I$3:$I$53,"P3") -> 1 | G17: =COUNTIF('12 Users, Roles & Perms'!$D$3:$D$53,"Web") -> 41 | H17: =COUNTIF('12 Users, Roles & Perms'!$D$3:$D$53,"iOS") -> 1 | I17: =COUNTIF('12 Users, Roles & Perms'!$D$3:$D$53,"Web + iOS") -> 9 | J17: =SUM('12 Users, Roles & Perms'!$K$3:$K$53) -> 1369 | K17: =J17/60 -> 22.816667 | L17: =COUNTIF('12 Users, Roles & Perms'!$L$3:$L$53,"Pass") -> 0 | M17: =COUNTIF('12 Users, Roles & Perms'!$L$3:$L$53,"Fail") -> 0 | N17: =COUNTIF('12 Users, Roles & Perms'!$L$3:$L$53,"Blocked") -> 0 | O17: =COUNTIF('12 Users, Roles & Perms'!$L$3:$L$53,"Not Run") -> 51 | P17: =IFERROR((L17+M17+N17)/C17,0) -> 0 | Q17: =IFERROR(L17/(L17+M17+N17),0) -> 0
B18: Sync Console & D365 | C18: =COUNTA('13 Sync Console & D365'!$A$3:$A$27) -> 25 | D18: =COUNTIF('13 Sync Console & D365'!$I$3:$I$27,"P1") -> 20 | E18: =COUNTIF('13 Sync Console & D365'!$I$3:$I$27,"P2") -> 5 | F18: =COUNTIF('13 Sync Console & D365'!$I$3:$I$27,"P3") -> 0 | G18: =COUNTIF('13 Sync Console & D365'!$D$3:$D$27,"Web") -> 24 | H18: =COUNTIF('13 Sync Console & D365'!$D$3:$D$27,"iOS") -> 0 | I18: =COUNTIF('13 Sync Console & D365'!$D$3:$D$27,"Web + iOS") -> 1 | J18: =SUM('13 Sync Console & D365'!$K$3:$K$27) -> 961 | K18: =J18/60 -> 16.016667 | L18: =COUNTIF('13 Sync Console & D365'!$L$3:$L$27,"Pass") -> 0 | M18: =COUNTIF('13 Sync Console & D365'!$L$3:$L$27,"Fail") -> 0 | N18: =COUNTIF('13 Sync Console & D365'!$L$3:$L$27,"Blocked") -> 0 | O18: =COUNTIF('13 Sync Console & D365'!$L$3:$L$27,"Not Run") -> 25 | P18: =IFERROR((L18+M18+N18)/C18,0) -> 0 | Q18: =IFERROR(L18/(L18+M18+N18),0) -> 0
B19: iOS Offline & Sync | C19: =COUNTA('14 iOS Offline & Sync'!$A$3:$A$31) -> 29 | D19: =COUNTIF('14 iOS Offline & Sync'!$I$3:$I$31,"P1") -> 23 | E19: =COUNTIF('14 iOS Offline & Sync'!$I$3:$I$31,"P2") -> 6 | F19: =COUNTIF('14 iOS Offline & Sync'!$I$3:$I$31,"P3") -> 0 | G19: =COUNTIF('14 iOS Offline & Sync'!$D$3:$D$31,"Web") -> 0 | H19: =COUNTIF('14 iOS Offline & Sync'!$D$3:$D$31,"iOS") -> 29 | I19: =COUNTIF('14 iOS Offline & Sync'!$D$3:$D$31,"Web + iOS") -> 0 | J19: =SUM('14 iOS Offline & Sync'!$K$3:$K$31) -> 985 | K19: =J19/60 -> 16.416667 | L19: =COUNTIF('14 iOS Offline & Sync'!$L$3:$L$31,"Pass") -> 0 | M19: =COUNTIF('14 iOS Offline & Sync'!$L$3:$L$31,"Fail") -> 0 | N19: =COUNTIF('14 iOS Offline & Sync'!$L$3:$L$31,"Blocked") -> 0 | O19: =COUNTIF('14 iOS Offline & Sync'!$L$3:$L$31,"Not Run") -> 29 | P19: =IFERROR((L19+M19+N19)/C19,0) -> 0 | Q19: =IFERROR(L19/(L19+M19+N19),0) -> 0
B20: Attachments & PDF Export | C20: =COUNTA('15 Attachments & PDF'!$A$3:$A$42) -> 40 | D20: =COUNTIF('15 Attachments & PDF'!$I$3:$I$42,"P1") -> 29 | E20: =COUNTIF('15 Attachments & PDF'!$I$3:$I$42,"P2") -> 8 | F20: =COUNTIF('15 Attachments & PDF'!$I$3:$I$42,"P3") -> 3 | G20: =COUNTIF('15 Attachments & PDF'!$D$3:$D$42,"Web") -> 31 | H20: =COUNTIF('15 Attachments & PDF'!$D$3:$D$42,"iOS") -> 6 | I20: =COUNTIF('15 Attachments & PDF'!$D$3:$D$42,"Web + iOS") -> 3 | J20: =SUM('15 Attachments & PDF'!$K$3:$K$42) -> 1010 | K20: =J20/60 -> 16.833333 | L20: =COUNTIF('15 Attachments & PDF'!$L$3:$L$42,"Pass") -> 0 | M20: =COUNTIF('15 Attachments & PDF'!$L$3:$L$42,"Fail") -> 0 | N20: =COUNTIF('15 Attachments & PDF'!$L$3:$L$42,"Blocked") -> 0 | O20: =COUNTIF('15 Attachments & PDF'!$L$3:$L$42,"Not Run") -> 40 | P20: =IFERROR((L20+M20+N20)/C20,0) -> 0 | Q20: =IFERROR(L20/(L20+M20+N20),0) -> 0
B21: Weather & Location Tracking | C21: =COUNTA('16 Weather & Tracking'!$A$3:$A$37) -> 35 | D21: =COUNTIF('16 Weather & Tracking'!$I$3:$I$37,"P1") -> 23 | E21: =COUNTIF('16 Weather & Tracking'!$I$3:$I$37,"P2") -> 12 | F21: =COUNTIF('16 Weather & Tracking'!$I$3:$I$37,"P3") -> 0 | G21: =COUNTIF('16 Weather & Tracking'!$D$3:$D$37,"Web") -> 16 | H21: =COUNTIF('16 Weather & Tracking'!$D$3:$D$37,"iOS") -> 19 | I21: =COUNTIF('16 Weather & Tracking'!$D$3:$D$37,"Web + iOS") -> 0 | J21: =SUM('16 Weather & Tracking'!$K$3:$K$37) -> 1025 | K21: =J21/60 -> 17.083333 | L21: =COUNTIF('16 Weather & Tracking'!$L$3:$L$37,"Pass") -> 0 | M21: =COUNTIF('16 Weather & Tracking'!$L$3:$L$37,"Fail") -> 0 | N21: =COUNTIF('16 Weather & Tracking'!$L$3:$L$37,"Blocked") -> 0 | O21: =COUNTIF('16 Weather & Tracking'!$L$3:$L$37,"Not Run") -> 35 | P21: =IFERROR((L21+M21+N21)/C21,0) -> 0 | Q21: =IFERROR(L21/(L21+M21+N21),0) -> 0
B22: Cross-Cutting & NFR | C22: =COUNTA('17 Cross-Cutting & NFR'!$A$3:$A$32) -> 30 | D22: =COUNTIF('17 Cross-Cutting & NFR'!$I$3:$I$32,"P1") -> 21 | E22: =COUNTIF('17 Cross-Cutting & NFR'!$I$3:$I$32,"P2") -> 7 | F22: =COUNTIF('17 Cross-Cutting & NFR'!$I$3:$I$32,"P3") -> 2 | G22: =COUNTIF('17 Cross-Cutting & NFR'!$D$3:$D$32,"Web") -> 25 | H22: =COUNTIF('17 Cross-Cutting & NFR'!$D$3:$D$32,"iOS") -> 1 | I22: =COUNTIF('17 Cross-Cutting & NFR'!$D$3:$D$32,"Web + iOS") -> 4 | J22: =SUM('17 Cross-Cutting & NFR'!$K$3:$K$32) -> 1210 | K22: =J22/60 -> 20.166667 | L22: =COUNTIF('17 Cross-Cutting & NFR'!$L$3:$L$32,"Pass") -> 0 | M22: =COUNTIF('17 Cross-Cutting & NFR'!$L$3:$L$32,"Fail") -> 0 | N22: =COUNTIF('17 Cross-Cutting & NFR'!$L$3:$L$32,"Blocked") -> 0 | O22: =COUNTIF('17 Cross-Cutting & NFR'!$L$3:$L$32,"Not Run") -> 30 | P22: =IFERROR((L22+M22+N22)/C22,0) -> 0 | Q22: =IFERROR(L22/(L22+M22+N22),0) -> 0
B23: TOTAL | C23: =SUM(C6:C22) -> 796 | D23: =SUM(D6:D22) -> 495 | E23: =SUM(E6:E22) -> 280 | F23: =SUM(F6:F22) -> 21 | G23: =SUM(G6:G22) -> 590 | H23: =SUM(H6:H22) -> 163 | I23: =SUM(I6:I22) -> 43 | J23: =SUM(J6:J22) -> 18972 | ... O23: =SUM(O6:O22) -> 796 | P23: =IFERROR((L23+M23+N23)/C23,0) -> 0 | Q23: =IFERROR(L23/(L23+M23+N23),0) -> 0
B26: Cycle planning
B27: Total test cases | G27: =C23 -> 796
B28: Total manual effort (hours) | G28: =K23 -> 316.2
B29: Total manual effort (person-days @ 6 productive hrs) | G29: =IFERROR(K23/6,0) -> 52.7
B30: Full regression - elapsed days, 1 tester | G30: =IFERROR(K23/6,0) -> 52.7
B31: Full regression - elapsed days, 2 testers | G31: =IFERROR(K23/12,0) -> 26.35
B32: Full regression - elapsed days, 3 testers | G32: =IFERROR(K23/18,0) -> 17.566667
B33: Contingency for defect logging & re-test (+30%) | G33: =IFERROR(K23*0.3,0) -> 94.86
B34: Recommended budget including contingency (hours) | G34: =IFERROR(K23*1.3,0) -> 411.06
B35: P1 (critical) cases | G35: =D23 -> 495
B36: Web-only cases | G36: =G23 -> 590
B37: iOS-only cases | G37: =H23 -> 163
B38: Cross-platform (Web + iOS) cases | G38: =I23 -> 43
B39: Open defects on the Defect Log | G39: =COUNTIF('Defect Log'!$H$3:$H$200,"Open") -> 1
B40: High-severity open defects | G40: =COUNTIFS('Defect Log'!$G$3:$G$200,"High",'Defect Log'!$H$3:$H$200,"Open") -> 1
B41: Overall pass rate (executed cases) | G41: =Q23 -> 0
B42: Execution coverage | G42: =P23 -> 0
B43: Health score (pass rate x execution coverage) | G43: =IFERROR(P23*Q23,0) -> 0
B45: Health score reading: >= 95% healthy | 85-94% acceptable, fix P1 failures before sign-off | < 85% not fit for release

Sheet 01 Global & Navigation
A1: AgriERP / AgriFarm - Vann Brothers Regression Suite | Global & Navigation
A2: TC-ID | B2: Module | C2: Sub-Process | D2: Platform | E2: Prerequisite | F2: Test Case | G2: Steps / Action | H2: Expected Result | I2: Priority | J2: Type | K2: Estimate (min) | L2: Status | M2: Actual Result | N2: Comments
A3: GN-001 | B3: Global & Navigation | C3: Authentication | D3: Web | E3: Valid AgriERP QA credentials (Azure AD / f3dynamics.onmicrosoft.com) | F3: Verify login to the AgriFarm web app with valid credentials | G3: 1. Open https://agrierp-vann-qa.folio3.site 2. Enter a valid username and password 3. Complete MFA if prompted | H3: The identity provider authenticates the user, the app lands on the default module, and the header shows the user's Grower, Site and Season. | I3: P1 | J3: Functional | K3: 12 | L3: Not Run
A4: GN-002 | B4: Global & Navigation | C4: Authentication | D4: Web | E4: Valid username | F4: Verify login is rejected with an invalid password | G4: 1. Enter a valid username with an incorrect password 2. Submit | H4: Login fails with a clear error from the identity provider; no partial session is created and the user is not routed into the app shell. | I4: P1 | J4: Negative | K4: 10 | L4: Not Run
A5: GN-003 | B5: Global & Navigation | C5: Authentication | D5: Web | E5: None | F5: Verify unauthenticated deep-link access is blocked | G5: 1. In a fresh/incognito browser open https://agrierp-vann-qa.folio3.site/workorders directly | H5: User is redirected to the sign-in page; after successful sign-in the originally requested route is restored. | I5: P1 | J5: Security | K5: 12 | L5: Not Run
A6: GN-004 | B6: Global & Navigation | C6: Authentication | D6: Web | E6: Logged-in session | F6: Verify Log Out terminates the session | G6: 1. Click the avatar (top-right) 2. Click 'Log Out' 3. After redirect press browser Back | H6: Session is terminated, the sign-in page is shown, and Back does not restore any authenticated page or cached data. | I6: P1 | J6: Security | K6: 12 | L6: Not Run
A7: GN-005 | B7: Global & Navigation | C7: Authentication | D7: Web | E7: Logged-in session | F7: Verify session expiry / silent token refresh behaviour | G7: 1. Log in and leave the app idle beyond the configured token lifetime 2. Return and click any module | H7: Either the token refreshes silently and the action succeeds, or the user is cleanly redirected to sign-in. The app never shows a blank screen or an unhandled 401. | I7: P2 | J7: Functional | K7: 30 | L7: Not Run
A8: GN-006 | B8: Global & Navigation | C8: Authentication | D8: Web | E8: Account exists in D365 but not provisioned in AgriERP | F8: Verify an unprovisioned but authenticated account is handled | G8: 1. Authenticate with an account that has no AgriERP user record 2. Observe the landing behaviour | H8: A clear 'no access / not provisioned' message is shown. The user is not dropped into an empty shell with broken module calls. | I8: P1 | J8: Negative | K8: 20 | L8: Not Run
A9: GN-007 | B9: Global & Navigation | C9: Authentication | D9: Web | E9: A user set to Inactive in Settings > User Management | F9: Verify an inactive user cannot access the application | G9: 1. Deactivate a user via Settings > Users 2. Attempt to sign in as that user | H9: Sign-in is blocked with an explicit message stating the account is inactive; any pre-existing session for that user is invalidated on next request. | I9: P1 | J9: Security | K9: 20 | L9: Not Run
A10: GN-008 | B10: Global & Navigation | C10: Authentication | D10: iOS | E10: AgriERP iOS build installed on iPhone/iPad, valid credentials | F10: Verify login to the iOS app with valid credentials | G10: 1. Launch the AgriERP app 2. Enter valid credentials on the login screen 3. Complete MFA if prompted | H10: The user is authenticated, the dashboard tiles render, and the profile shows the correct Grower, Location and Season. | I10: P1 | J10: Functional | K10: 15 | L10: Not Run
A11: GN-009 | B11: Global & Navigation | C11: Authentication | D11: iOS | E11: iOS app installed | F11: Verify login is rejected with invalid credentials on iOS | G11: 1. Enter an incorrect password and submit 2. Repeat with a non-existent username | H11: Both attempts fail with a readable in-app error; the app does not crash, hang on a spinner, or cache the failed credentials. | I11: P1 | J11: Negative | K11: 12 | L11: Not Run
A12: GN-010 | B12: Global & Navigation | C12: Authentication | D12: iOS | E12: Logged-in iOS session | F12: Verify the iOS session persists across an app restart | G12: 1. Log in 2. Force-quit the app from the app switcher 3. Relaunch | H12: The user remains signed in and lands on the dashboard without re-entering credentials, provided the token is still valid. | I12: P1 | J12: Functional | K12: 12 | L12: Not Run
A13: GN-011 | B13: Global & Navigation | C13: Authentication | D13: iOS | E13: Logged-in iOS session | F13: Verify Log Out on iOS clears local data | G13: 1. Log out from the app menu 2. Relaunch the app 3. Attempt to open a previously cached work order offline | H13: Login screen is shown, no cached work-order data is reachable without authenticating, and the local store is cleared per the security policy. | I13: P1 | J13: Security | K13: 20 | L13: Not Run
A14: GN-012 | B14: Global & Navigation | C14: Authentication | D14: Web + iOS | E14: Same user account | F14: Verify concurrent sessions on web and iOS are supported | G14: 1. Log in on web and on the iOS app with the same account 2. Perform an action on each | H14: Both sessions remain valid and functional; actions on one platform do not silently invalidate the other unless single-session policy is configured. | I14: P2 | J14: Functional | K14: 20 | L14: Not Run
... A62: GN-060 | B62: Global & Navigation | C62: iOS - Accessibility | D62: iOS | E62: Logged-in iOS session | F62: Verify Dynamic Type and dark mode do not break layouts | G62: 1. Set a larger text size in iOS Settings and enable dark mode 2. Navigate the main screens | H62: Text scales without clipping or overlap, contrast remains legible in dark mode, and no control becomes unreachable. | I62: P3 | J62: Accessibility | K62: 25 | L62: Not Run
J64: Total estimate (min) | K64: =SUM(K3:K62) -> 1061
J65: Total estimate (hrs) | K65: =K64/60 -> 17.683333

Sheet 02 Maps
A1: AgriERP / AgriFarm - Vann Brothers Regression Suite | Maps
A2: TC-ID | B2: Module | C2: Sub-Process | D2: Platform | E2: Prerequisite | F2: Test Case | G2: Steps / Action | H2: Expected Result | I2: Priority | J2: Type | K2: Estimate (min) | L2: Status | M2: Actual Result | N2: Comments
A3: MP-001 | B3: Maps | C3: Map Load | D3: Web | E3: Logged-in user, site and season selected | F3: Verify the Maps module loads the farm boundary and field polygons | G3: 1. Click Maps in the header 2. Wait for the map to render | H3: The map renders centred on the selected farm with all field polygons drawn and labelled; no console errors and no missing tiles. | I3: P1 | J3: Functional | K3: 12 | L3: Not Run
A4: MP-002 | B4: Maps | C4: Map Load | D4: Web | E4: Maps open | F4: Verify farm summary counters are correct | G4: 1. Open the Details aside > Summary tab 2. Compare with the sidebar tree | H4: Farm Name, Location, No of Fields and Total Area are shown and reconcile exactly with the sidebar field list. | I4: P1 | J4: Data | K4: 20 | L4: Not Run
A5: MP-003 | B5: Maps | C5: Map Load | D5: Web | E5: A site or season with unmapped fields | F5: Verify empty/partial geometry handling | G5: 1. Switch to a site or season containing fields with no boundary geometry | H5: The map still renders; unmapped fields are omitted or clearly flagged; no JavaScript error and no infinite loading state. | I5: P2 | J5: Negative | K5: 18 | L5: Not Run
A6: MP-004 | B6: Maps | C6: Map Load | D6: Web | E6: Maps open | F6: Verify map load time with the full QA dataset | G6: 1. Hard-refresh Maps and measure time to first fully rendered polygon set 2. Repeat three times and take the median | H6: The map reaches a usable rendered state within the agreed threshold; the measured value is recorded in Comments for trend tracking. | I6: P2 | J6: Performance | K6: 25 | L6: Not Run
A7: MP-005 | B7: Maps | C7: Map Type | D7: Web | E7: Maps open | F7: Verify the Map / Satellite base-layer toggle | G7: 1. Click 'Satellite' 2. Click 'Map' | H7: The base layer switches between roadmap and satellite imagery; field polygons and labels stay aligned and visible in both. | I7: P2 | J7: Functional | K7: 10 | L7: Not Run
A8: MP-006 | B8: Maps | C8: Map Type | D8: Web | E8: Satellite view active | F8: Verify the Terrain and Labels sub-options | G8: 1. Hover the base-layer control 2. Toggle 'Terrain' and 'Labels' | H8: Terrain shading and place labels are applied and removed without losing the field overlay. | I8: P3 | J8: Functional | K8: 10 | L8: Not Run
A9: MP-007 | B9: Maps | C9: Map Controls | D9: Web | E9: Maps open | F9: Verify zoom in / zoom out controls | G9: 1. Click Zoom in three times, then Zoom out three times | H9: The zoom level changes smoothly, polygons and labels rescale correctly, and the view returns to a comparable extent. | I9: P2 | J9: Functional | K9: 10 | L9: Not Run
A10: MP-008 | B10: Maps | C10: Map Controls | D10: Web | E10: Maps open | F10: Verify the fullscreen toggle | G10: 1. Click 'Toggle fullscreen view' 2. Press Esc | H10: The map expands to fullscreen and restores correctly; controls and the layer panel remain usable in both states. | I10: P3 | J10: Functional | K10: 10 | L10: Not Run
A11: MP-009 | B11: Maps | C11: Map Controls | D11: Web | E11: Maps open | F11: Verify pan and drag behaviour | G11: 1. Click and drag the map in several directions | H11: The map pans smoothly, tiles load progressively and field overlays stay aligned with the base imagery. | I11: P3 | J11: Functional | K11: 10 | L11: Not Run
A12: MP-010 | B12: Maps | C12: Map Controls | D12: Web | E12: Maps open | F12: Verify Street View (Pegman) behaves gracefully | G12: 1. Drag Pegman onto a road near a field | H12: Street View opens where imagery exists; where it does not, the control degrades gracefully without a broken panel. | I12: P3 | J12: Functional | K12: 12 | L12: Not Run
A13: MP-011 | B13: Maps | C13: Maps Control - Layers | D13: Web | E13: Maps open | F13: Verify the Maps Control panel lists all configured layers | G13: 1. Click 'Maps Control' | H13: The panel lists Stages, Crops, Task/Operation, Active/Draft/Completed Inspections, Upcoming/Active/Completed Work Orders, Observations and Point of Interest. | I13: P1 | J13: Functional | K13: 12 | L13: Not Run
A14: MP-012 | B14: Maps | C14: Maps Control - Layers | D14: Web | E14: Maps Control open | F14: Verify the Crops layer colour-codes fields by crop | G14: 1. Select the Crops layer 2. Observe the map and legend | H14: Fields are shaded by crop/variety with a legend matching the shading; field labels remain readable over the fill. | I14: P2 | J14: Functional | K14: 15 | L14: Not Run
... A63: MP-061 | B63: Maps | C63: iOS - Map Tile | D63: iOS | E63: Device with intermittent connectivity | F63: Verify map behaviour when the network drops mid-render | G63: 1. Open the map, then disable the network while tiles are loading | H63: The app shows an offline/no-connection indicator, retains any already-rendered data, and recovers when connectivity returns without a restart. | I63: P1 | J63: Negative | K63: 30 | L63: Not Run
J65: Total estimate (min) | K65: =SUM(K3:K63) -> 1157
J66: Total estimate (hrs) | K66: =K65/60 -> 19.283333

Sheet 03 Planning
A1: AgriERP / AgriFarm - Vann Brothers Regression Suite | Planning
A2: TC-ID | B2: Module | C2: Sub-Process | D2: Platform | E2: Prerequisite | F2: Test Case | G2: Steps / Action | H2: Expected Result | I2: Priority | J2: Type | K2: Estimate (min) | L2: Status | M2: Actual Result | N2: Comments
A3: PL-001 | B3: Planning | C3: Module Load | D3: Web | E3: Logged-in user, site and season selected | F3: Verify the Planning module opens with the farm tree | G3: 1. Click 'Planning' in the header | H3: The route resolves to /crop-mgmt, the left sidebar renders the farm/field tree and the work area shows a clear empty-state prompt until a plot is chosen. | I3: P2 | J3: Functional | K3: 12 | L3: Not Run
A4: PL-002 | B4: Planning | C4: D365 Sync | D4: Web | E4: A project created and published in D365 F&O | F4: Verify a project syncs from D365 into the Planning tab | G4: 1. Create and publish a project in D365 2. Wait for the sync batch job 3. Open Planning and locate the project | H4: The project appears in the Planning tab within the expected sync window, with its job number, job name and growing item intact. | I4: P1 | J4: Integration | K4: 40 | L4: Not Run
A5: PL-003 | B5: Planning | C5: D365 Sync | D5: Web | E5: Projects synced for more than one farm | F5: Verify each project is associated with the correct farm | G5: 1. Browse the farm panel and inspect the projects under each farm | H5: Each project appears only under its associated farm; no project is duplicated across farms. | I5: P1 | J5: Data | K5: 25 | L5: Not Run
A6: PL-004 | B6: Planning | C6: D365 Sync | D6: Web | E6: A project created for a specific plot in D365 | F6: Verify project-to-plot association | G6: 1. Sync the project 2. Locate it in Planning | H6: The project appears only under the correct plot within the correct farm. | I6: P1 | J6: Data | K6: 25 | L6: Not Run
A7: PL-005 | B7: Planning | C7: D365 Sync | D7: Web | E7: A synced project with multiple operations | F7: Verify project data integrity after sync | G7: 1. Compare every operation, stage and date on the D365 project against the Planning board | H7: All operations, stages and dates match exactly between D365 and the Farm App with no dropped or renamed lines. | I7: P1 | J7: Data | K7: 40 | L7: Not Run
A8: PL-006 | B8: Planning | C8: D365 Sync | D8: Web | E8: An operation created in D365 with no stage assigned | F8: Verify an operation without a stage is not displayed | G8: 1. Create an operation with no stage in D365 2. Sync and inspect every stage in Planning | H8: The unassigned operation does not appear under any stage and does not silently attach to the first stage. | I8: P2 | J8: Negative | K8: 25 | L8: Not Run
A9: PL-007 | B9: Planning | C9: Plot Selection | D9: Web | E9: Planning open | F9: Verify expanding a field reveals its plots | G9: 1. Click a field node in the sidebar | H9: The node expands showing its plots with project code, crop and primary/secondary designation, and the correct plot count. | I9: P1 | J9: Functional | K9: 12 | L9: Not Run
A10: PL-008 | B10: Planning | C10: Plot Selection | D10: Web | E10: A field expanded | F10: Verify selecting a plot loads its planning board | G10: 1. Click a plot node | H10: The work-area header shows Field | Season code - PRJ_xxxxxx | Crop, and the stages and activity cards load for that plot. | I10: P1 | J10: Functional | K10: 15 | L10: Not Run
A11: PL-009 | B11: Planning | C11: Plot Selection | D11: Web | E11: A plot selected | F11: Verify switching to another plot fully reloads the board | G11: 1. Select a different plot in the tree | H11: Header, stages and activity cards all refresh for the newly selected plot with no residual data from the previous plot. | I11: P1 | J11: Functional | K11: 15 | L11: Not Run
A12: PL-010 | B12: Planning | C12: Plot Selection | D12: Web | E12: Planning open | F12: Verify sidebar search locates a plot by project code or field number | G12: 1. Type a project code into the sidebar Search box 2. Select the result | H12: Matching nodes are filtered and the selected plot loads correctly; clearing the search restores the tree. | I12: P2 | J12: Functional | K12: 12 | L12: Not Run
A13: PL-011 | B13: Planning | C13: Plot Configuration | D13: Web | E13: A plot selected | F13: Verify the Plot Configuration panel shows plot attributes | G13: 1. Click 'Plot Configuration' | H13: The panel expands showing Crop, Plot Area (ac) and No. of rows / Plot for the selected plot. | I13: P2 | J13: Functional | K13: 12 | L13: Not Run
A14: PL-012 | B14: Planning | C14: Plot Configuration | D14: Web | E14: Plot Configuration open | F14: Verify plot area matches the Maps module and the field record | G14: 1. Note Plot Area in Plot Configuration 2. Compare with the same plot/field acreage on Maps | H14: Values are identical to two decimal places across Planning, Maps and the underlying field record. | I14: P1 | J14: Data | K14: 20 | L14: Not Run
... A43: PL-041 | B43: Planning | C43: Planning - Permissions | D43: Web | E43: A non-manager role account | F43: Verify Planning respects role permissions | G43: 1. Open Planning as a restricted role 2. Attempt any create/edit action offered | H43: Read-only roles can browse but cannot trigger creation or edits; restricted actions are hidden and rejected server-side. | I43: P1 | J43: Security | K43: 25 | L43: Not Run
J45: Total estimate (min) | K45: =SUM(K3:K43) -> 828
J46: Total estimate (hrs) | K46: =K45/60 -> 13.8

Sheet 04 WO - Planned
A1: AgriERP / AgriFarm - Vann Brothers Regression Suite | Work Orders - Planned
A2: TC-ID | B2: Module | C2: Sub-Process | D2: Platform | E2: Prerequisite | F2: Test Case | G2: Steps / Action | H2: Expected Result | I2: Priority | J2: Type | K2: Estimate (min) | L2: Status | M2: Actual Result | N2: Comments
A3: WP-001 | B3: Work Orders - Planned | C3: List - Load | D3: Web | E3: Logged-in user, site and season selected | F3: Verify the Work Orders module loads the default list | G3: 1. Click 'Work Orders' in the header | H3: The route resolves to /workorders, the Work Orders tab is active, the 'All' status filter is selected and the grid renders with data. | I3: P1 | J3: Functional | K3: 10 | L3: Not Run
A4: WP-002 | B4: Work Orders - Planned | C4: List - Columns | D4: Web | E4: Work Orders list open | F4: Verify all expected columns are present | G4: 1. Inspect the grid header | H4: Columns are WO Sequence No., WO Name, Priority, WO Start Date, WO End Date, Farm, Plots, Progress, Task, Materials, Status, Submitted By, Responsible and Actions. | I4: P2 | J4: UI | K4: 10 | L4: Not Run
A5: WP-003 | B5: Work Orders - Planned | C5: List - Tabs | D5: Web | E5: Work Orders list open | F5: Verify the work-order type tabs are present and switchable | G5: 1. Click Work Orders, Inspection Work Orders, Harvest Work Orders and Observations in turn | H5: Each tab loads its own dataset and column set without error and the active tab is highlighted. | I5: P2 | J5: Functional | K5: 15 | L5: Not Run
A6: WP-004 | B6: Work Orders - Planned | C6: List - Status Filters | D6: Web | E6: Work Orders list open | F6: Verify the status filter chips are present | G6: 1. Inspect the filter row | H6: Chips are All, Queue, Draft, To Do, In Progress, Review and Done. | I6: P2 | J6: UI | K6: 8 | L6: Not Run
A7: WP-005 | B7: Work Orders - Planned | C7: List - Status Filters | D7: Web | E7: Work Orders list open | F7: Verify each status filter returns only matching work orders | G7: 1. Click each status chip in turn 2. Inspect the Status column of the results | H7: Every returned row carries the selected status; 'All' returns the union and the record count updates each time. | I7: P1 | J7: Functional | K7: 25 | L7: Not Run
A8: WP-006 | B8: Work Orders - Planned | C8: List - Status Filters | D8: Web | E8: A status filter applied | F8: Verify the status filter combines with column search | G8: 1. Select 'To Do' 2. Search WO Name for a partial term | H8: Only rows matching both the status and the search term are returned. | I8: P2 | J8: Functional | K8: 15 | L8: Not Run
A9: WP-007 | B9: Work Orders - Planned | C9: List - Filter Panel | D9: Web | E9: Work Orders list open | F9: Verify the advanced filter panel opens with Apply and Reset | G9: 1. Click 'Filter' | H9: The panel opens with its criteria plus working Reset and Apply actions. | I9: P2 | J9: Functional | K9: 12 | L9: Not Run
A10: WP-008 | B10: Work Orders - Planned | C10: List - Filter Panel | D10: Web | E10: Filter panel open | F10: Verify Apply and Reset behaviour | G10: 1. Set several criteria and click Apply 2. Reopen the panel and click Reset | H10: Apply narrows the grid to the criteria; Reset clears all criteria and restores the unfiltered grid. | I10: P2 | J10: Functional | K10: 18 | L10: Not Run
A11: WP-009 | B11: Work Orders - Planned | C11: List - Search | D11: Web | E11: Work Orders list open | F11: Verify search by work order number and name | G11: 1. Search by full WO sequence number 2. Search by a partial WO name | H11: Both searches return the correct rows; a search matching nothing shows a clear empty state. | I11: P2 | J11: Functional | K11: 15 | L11: Not Run
A12: WP-010 | B12: Work Orders - Planned | C12: List - Data | D12: Web | E12: Work Orders list open | F12: Verify date formatting and ordering | G12: 1. Inspect WO Start Date and WO End Date across rows | H12: Dates render in the configured format and End Date is never earlier than Start Date on any row. | I12: P1 | J12: Data | K12: 18 | L12: Not Run
A13: WP-011 | B13: Work Orders - Planned | C13: List - Data | D13: Web | E13: A multi-plot work order exists | F13: Verify the Plots column lists all plots | G13: 1. Find a work order with more than one plot 2. Open its detail and compare | H13: Every plot shown in the grid is present on the detail and vice versa, with no truncation losing data. | I13: P2 | J13: Data | K13: 18 | L13: Not Run
A14: WP-012 | B14: Work Orders - Planned | C14: List - Data | D14: Web | E14: A work order with several materials | F14: Verify the Materials cell popover shows the full material list | G14: 1. Hover/click the Materials cell | H14: A popover lists all assigned materials; grid truncation does not hide any entry. | I14: P2 | J14: UI | K14: 12 | L14: Not Run
... A97: WP-095 | B97: Work Orders - Planned | C97: Load | D97: Web + iOS | E97: One work order open by several users | F97: Verify concurrent progress entry by multiple users | G97: 1. Have four or more users enter progress on different plots of the same work order simultaneously | H97: All entries are saved, no deadlock or lost update occurs, and the aggregate work order progress is arithmetically correct. | I97: P1 | J97: Performance | K97: 60 | L97: Not Run
J99: Total estimate (min) | K99: =SUM(K3:K97) -> 2176
J100: Total estimate (hrs) | K100: =K99/60 -> 36.266667

Sheet 05 WO - Inspection
A1: AgriERP / AgriFarm - Vann Brothers Regression Suite | Work Orders - Inspection
A2: TC-ID | B2: Module | C2: Sub-Process | D2: Platform | E2: Prerequisite | F2: Test Case | G2: Steps / Action | H2: Expected Result | I2: Priority | J2: Type | K2: Estimate (min) | L2: Status | M2: Actual Result | N2: Comments
A3: WI-001 | B3: Work Orders - Inspection | C3: List - Load | D3: Web | E3: Work Orders module open | F3: Verify the Inspection Work Orders tab loads | G3: 1. Click the 'Inspection Work Orders' tab | H3: The tab loads its own dataset without error and only inspection-type work orders are listed. | I3: P1 | J3: Functional | K3: 10 | L3: Not Run
A4: WI-002 | B4: Work Orders - Inspection | C4: List - Columns | D4: Web | E4: Inspection Work Orders tab open | F4: Verify the Inspection Work Orders column set | G4: 1. Inspect the grid header | H4: Columns include WO Sequence No., WO Name, Priority, Start/End Date, Farm, Plots, Progress, Task, Inspection Template, Status, Submitted By and Actions. | I4: P2 | J4: UI | K4: 10 | L4: Not Run
A5: WI-003 | B5: Work Orders - Inspection | C5: List - Filters | D5: Web | E5: Inspection Work Orders tab open | F5: Verify status filters and column search on the inspection list | G5: 1. Apply each status chip, then search by WO Name and by Inspection Template | H5: Filtering and searching return only matching inspection work orders and combine correctly. | I5: P2 | J5: Functional | K5: 20 | L5: Not Run
A6: WI-004 | B6: Work Orders - Inspection | C6: Create | D6: Web | E6: An Active/Published inspection template exists | F6: Verify Inspection Work Order creation | G6: 1. Click Create New Work Order 2. Select the Inspection type 3. Select an active inspection template 4. Complete required fields and submit | H6: The inspection work order is created successfully with the selected template attached and moves to To Do. | I6: P1 | J6: Functional | K6: 25 | L6: Not Run
A7: WI-005 | B7: Work Orders - Inspection | C7: Create | D7: Web | E7: Both active and inactive templates exist | F7: Verify only active templates are offered | G7: 1. Open the inspection template dropdown on the create form | H7: Only active/published templates are listed; draft and disabled templates are excluded. | I7: P1 | J7: Functional | K7: 15 | L7: Not Run
A8: WI-006 | B8: Work Orders - Inspection | C8: Create | D8: Web | E8: Create form set to Inspection type | F8: Verify Supervisor and Responsible fields are disabled for inspection work orders | G8: 1. Inspect the resources section on the create form | H8: Supervisor and Responsible fields are disabled or absent as designed for inspection work orders. | I8: P1 | J8: Functional | K8: 12 | L8: Not Run
A9: WI-007 | B9: Work Orders - Inspection | C9: Create | D9: Web | E9: Create form set to Inspection type | F9: Verify traditional progress entry is not offered | G9: 1. Inspect the form for acre/run progress inputs | H9: No traditional progress fields are present; progress derives solely from template attribute completion. | I9: P1 | J9: Functional | K9: 15 | L9: Not Run
A10: WI-008 | B10: Work Orders - Inspection | C10: Create | D10: Web | E10: Create form set to Inspection type | F10: Verify validation when no template is selected | G10: 1. Submit an inspection work order without selecting a template | H10: Submission is blocked with a clear message identifying the missing template. | I10: P1 | J10: Negative | K10: 12 | L10: Not Run
A11: WI-009 | B11: Work Orders - Inspection | C11: Create | D11: Web | E11: Create form set to Inspection type | F11: Verify plots can be added to an inspection work order | G11: 1. Set the task date range and add several plots | H11: Plots are added with their attributes and the total plot count updates correctly. | I11: P1 | J11: Functional | K11: 20 | L11: Not Run
A12: WI-010 | B12: Work Orders - Inspection | C12: Create | D12: Web | E12: Ad-hoc blocks permitted | F12: Verify ad-hoc blocks can be added to an inspection work order | G12: 1. Add a block not present on the D365 plan and submit | H12: The ad-hoc block is saved and appears on the mobile app for inspection. | I12: P2 | J12: Integration | K12: 25 | L12: Not Run
A13: WI-011 | B13: Work Orders - Inspection | C13: Submit | D13: Web | E13: A complete inspection work order draft | F13: Verify submission moves the inspection work order to To Do | G13: 1. Complete all required data and click Submit | H13: The status becomes To Do and the work order becomes visible to mobile users after sync. | I13: P1 | J13: Functional | K13: 18 | L13: Not Run
A14: WI-012 | B14: Work Orders - Inspection | C14: Mobile Sync | D14: Web + iOS | E14: A submitted inspection work order | F14: Verify the inspection work order syncs to iOS with template and locations | G14: 1. Sync the iOS app and open the inspection work order | H14: The work order appears with its plots, template and the configured default number of locations. | I14: P1 | J14: Integration | K14: 30 | L14: Not Run
... A47: WI-045 | B47: Work Orders - Inspection | C47: Negative | D47: iOS | E47: An inspection work order with no locations configured | F47: Verify handling of a template with zero default locations | G47: 1. Open an inspection work order whose template has no default locations | H47: The app shows a clear state and either allows the user to add a location or blocks with an explanatory message rather than crashing. | I47: P2 | J47: Negative | K47: 20 | L47: Not Run
J49: Total estimate (min) | K49: =SUM(K3:K47) -> 1110
J50: Total estimate (hrs) | K50: =K49/60 -> 18.5

Sheet 06 WO - Observations
A1: AgriERP / AgriFarm - Vann Brothers Regression Suite | Work Orders - Observations
A2: TC-ID | B2: Module | C2: Sub-Process | D2: Platform | E2: Prerequisite | F2: Test Case | G2: Steps / Action | H2: Expected Result | I2: Priority | J2: Type | K2: Estimate (min) | L2: Status | M2: Actual Result | N2: Comments
A3: WB-001 | B3: Work Orders - Observations | C3: List - Load | D3: Web | E3: Work Orders module open | F3: Verify the Observations tab loads without error | G3: 1. Click the 'Observations' tab | H3: Observation records load successfully. This tab has previously failed with an unknown error - confirm the fix. | I3: P1 | J3: Functional | K3: 15 | L3: Not Run
A4: WB-002 | B4: Work Orders - Observations | C4: List - Columns | D4: Web | E4: Observations tab open | F4: Verify the Observations column set | G4: 1. Inspect the grid header | H4: Columns are Title, Farm, Plots, Category, Created Date, Created By and Actions. | I4: P2 | J4: UI | K4: 10 | L4: Not Run
A5: WB-003 | B5: Work Orders - Observations | C5: List - Filters | D5: Web | E5: Observations tab open | F5: Verify search and filtering on the observations list | G5: 1. Search by Title and by Created By 2. Filter by Category | H5: Each search and filter returns only matching observations and can be cleared. | I5: P2 | J5: Functional | K5: 18 | L5: Not Run
A6: WB-004 | B6: Work Orders - Observations | C6: List - Season Scope | D6: Web | E6: Observations exist in more than one season | F6: Verify observations are filtered by the selected season | G6: 1. Note the observations listed for the current season 2. Switch season and re-inspect | H6: Only observations belonging to the selected season are listed; no cross-season leakage. | I6: P1 | J6: Data | K6: 25 | L6: Not Run
A7: WB-005 | B7: Work Orders - Observations | C7: Detail | D7: Web | E7: An observation exists | F7: Verify the observation detail opens from the details icon | G7: 1. Click the details icon on an observation row | H7: The detail view opens showing title, category, plot, season, comments, attachments and creator with timestamps. | I7: P1 | J7: Functional | K7: 18 | L7: Not Run
A8: WB-006 | B8: Work Orders - Observations | C8: Detail | D8: Web | E8: An observation with attachments | F8: Verify all attachment types are viewable on the web detail | G8: 1. Open an observation carrying photo, video, audio, document and map-drawing attachments | H8: Each attachment renders or plays correctly and can be downloaded; nothing appears as a broken link. | I8: P1 | J8: Functional | K8: 30 | L8: Not Run
A9: WB-007 | B9: Work Orders - Observations | C9: Create WO | D9: Web | E9: An observation exists | F9: Verify a work order can be created from an observation | G9: 1. Open the observation detail and click 'Create Work Order' | H9: The create work order form opens pre-populated with the plot and relevant context from the observation. | I9: P1 | J9: Functional | K9: 25 | L9: Not Run
A10: WB-008 | B10: Work Orders - Observations | C10: Create WO | D10: Web | E10: Work order creation started from an observation | F10: Verify the work order is created and linked back to the observation | G10: 1. Complete the required fields and submit | H10: The work order is created successfully and the link to the originating observation is retained and visible from both records. | I10: P1 | J10: Functional | K10: 30 | L10: Not Run
A11: WB-009 | B11: Work Orders - Observations | C11: POI Config | D11: Web | E11: Admin access to the map configuration screen | F11: Verify POI configuration is reachable under Map Config | G11: 1. Navigate to Settings > Map Toggle / POI Configuration | H11: The POI setup table is reachable by an authorised manager and is hidden from unauthorised roles. | I11: P1 | J11: Security | K11: 18 | L11: Not Run
A12: WB-010 | B12: Work Orders - Observations | C12: POI Config | D12: Web | E12: POI configuration open | F12: Verify POI categories can be created with title, colour and icon | G12: 1. Create a POI category with a title, colour and icon 2. Set the Visible and Enable toggles and save | H12: The category is created and appears in the configuration list with the chosen icon and colour. | I12: P1 | J12: Functional | K12: 25 | L12: Not Run
A13: WB-011 | B13: Work Orders - Observations | C13: POI Config | D13: Web | E13: POI categories configured | F13: Verify configured pins appear on the map for the block | G13: 1. Create an observation of a configured category 2. Open Maps and select the POI layer | H13: The pin appears on the correct block using the configured icon and colour. | I13: P1 | J13: Integration | K13: 30 | L13: Not Run
A14: WB-012 | B14: Work Orders - Observations | C14: POI Config | D14: Web | E14: POI categories with existing pins | F14: Verify changing a category colour does not alter historic pins | G14: 1. Change the colour of a category that already has pins 2. Re-inspect the map | H14: Previously placed pins retain their original colour per the agreed rule; only new pins use the new colour. | I14: P2 | J14: Data | K14: 30 | L14: Not Run
... A41: WB-039 | B41: Work Orders - Observations | C41: Permissions | D41: Web + iOS | E41: A restricted role account | F41: Verify observation visibility respects role and location rights | G41: 1. Create an observation as one user 2. Sign in as a user without rights to that location and search for it | H41: The observation is not visible to a user lacking rights to its location on either platform. | I41: P1 | J41: Security | K41: 30 | L41: Not Run
J43: Total estimate (min) | K43: =SUM(K3:K41) -> 829
J44: Total estimate (hrs) | K44: =K43/60 -> 13.816667

Sheet 07 WO - Harvest
A1: AgriERP / AgriFarm - Vann Brothers Regression Suite | Work Orders - Harvest
A2: TC-ID | B2: Module | C2: Sub-Process | D2: Platform | E2: Prerequisite | F2: Test Case | G2: Steps / Action | H2: Expected Result | I2: Priority | J2: Type | K2: Estimate (min) | L2: Status | M2: Actual Result | N2: Comments
A3: WH-001 | B3: Work Orders - Harvest | C3: List - Load | D3: Web | E3: Work Orders module open | F3: Verify the Harvest Work Orders tab loads | G3: 1. Click the 'Harvest Work Orders' tab | H3: Only harvest-type work orders are listed and the tab loads without error. | I3: P1 | J3: Functional | K3: 10 | L3: Not Run
A4: WH-002 | B4: Work Orders - Harvest | C4: List - Columns | D4: Web | E4: Harvest Work Orders tab open | F4: Verify the Harvest Work Orders column set and data | G4: 1. Inspect the grid header and rows | H4: Columns match the standard work order set, with harvest-specific data populated correctly. | I4: P2 | J4: UI | K4: 10 | L4: Not Run
A5: WH-003 | B5: Work Orders - Harvest | C5: Create | D5: Web | E5: Harvest task configured | F5: Verify creation of a harvest work order | G5: 1. Create a new work order selecting the harvest task type 2. Add plots, resources and assets and submit | H5: The harvest work order is created and appears under the Harvest Work Orders tab in To Do status. | I5: P1 | J5: Functional | K5: 30 | L5: Not Run
A6: WH-004 | B6: Work Orders - Harvest | C6: Create | D6: Web | E6: Harvest work order create form open | F6: Verify harvest-specific fields and validation | G6: 1. Inspect the form for harvest-specific fields and submit with them blank | H6: Harvest-specific mandatory fields are marked and enforced with clear inline validation. | I6: P1 | J6: Negative | K6: 20 | L6: Not Run
A7: WH-005 | B7: Work Orders - Harvest | C7: Mobile Sync | D7: Web + iOS | E7: A submitted harvest work order | F7: Verify the harvest work order syncs to iOS | G7: 1. Sync the iOS app and open the harvest work order | H7: The work order appears with its plots, resources, assets and harvest configuration. | I7: P1 | J7: Integration | K7: 25 | L7: Not Run
A8: WH-006 | B8: Work Orders - Harvest | C8: Mobile Execution | D8: iOS | E8: A harvest work order in To Do | F8: Verify Start Harvest ID | G8: 1. Start a harvest ID on the work order | H8: The harvest ID starts, is timestamped and is visible to the supervisor. | I8: P1 | J8: Functional | K8: 25 | L8: Not Run
A9: WH-007 | B9: Work Orders - Harvest | C9: Mobile Execution | D9: iOS | E9: Supervisor/Manager role | F9: Verify Start Harvest ID for another user | G9: 1. As a supervisor, start a harvest ID on behalf of another resource | H9: The harvest ID is attributed to the intended user and the acting user is recorded in the audit trail. | I9: P1 | J9: Functional | K9: 30 | L9: Not Run
A10: WH-008 | B10: Work Orders - Harvest | C10: Mobile Execution | D10: iOS | E10: An active harvest ID | F10: Verify Create Ticket | G10: 1. Create a harvest ticket against the active harvest ID | H10: The ticket is created with the correct harvest ID, plot, timestamp and creator. | I10: P1 | J10: Functional | K10: 25 | L10: Not Run
A11: WH-009 | B11: Work Orders - Harvest | C11: Mobile Execution | D11: iOS | E11: Supervisor/Manager role | F11: Verify Create Ticket for another user | G11: 1. Create a ticket on behalf of another resource | H11: The ticket is attributed to the intended user with the acting user recorded. | I11: P1 | J11: Functional | K11: 25 | L11: Not Run
A12: WH-010 | B12: Work Orders - Harvest | C12: Mobile Execution | D12: iOS | E12: A harvest ticket exists | F12: Verify Edit Ticket | G12: 1. Edit an existing ticket's values and save | H12: The changes are persisted and an edit history entry is recorded. | I12: P1 | J12: Functional | K12: 25 | L12: Not Run
A13: WH-011 | B13: Work Orders - Harvest | C13: Mobile Execution | D13: iOS | E13: Supervisor/Manager role and another user's ticket | F13: Verify Edit Ticket for another user | G13: 1. Edit a ticket belonging to another resource | H13: The edit is permitted only for privileged roles, is saved correctly and is attributed in the audit trail. | I13: P2 | J13: Security | K13: 25 | L13: Not Run
A14: WH-012 | B14: Work Orders - Harvest | C14: Mobile Execution | D14: iOS | E14: A harvest ticket exists | F14: Verify Link Harvest ID to a ticket | G14: 1. Link a harvest ID to an existing ticket | H14: The linkage is saved and visible on both the ticket and the harvest ID record. | I14: P1 | J14: Functional | K14: 25 | L14: Not Run
... A30: WH-028 | B30: Work Orders - Harvest | C30: Integration | D30: Web | E30: A completed harvest work order | F30: Verify harvest tickets created from the work order surface in Harvest Central | G30: 1. Complete a harvest work order that generated tickets 2. Open Harvest Central for the same field/variety | H30: The tickets appear under the correct field/variety with matching identifiers and quantities. | I30: P1 | J30: Integration | K30: 35 | L30: Not Run
J32: Total estimate (min) | K32: =SUM(K3:K30) -> 755
J33: Total estimate (hrs) | K33: =K32/60 -> 12.583333

Sheet 08 Harvest Central
A1: AgriERP / AgriFarm - Vann Brothers Regression Suite | Harvest Central
A2: TC-ID | B2: Module | C2: Sub-Process | D2: Platform | E2: Prerequisite | F2: Test Case | G2: Steps / Action | H2: Expected Result | I2: Priority | J2: Type | K2: Estimate (min) | L2: Status | M2: Actual Result | N2: Comments
A3: HC-001 | B3: Harvest Central | C3: List - Load | D3: Web | E3: Logged-in user, site and season selected | F3: Verify the Harvest Central module loads the field/variety list | G3: 1. Click 'Harvest Central' in the header | H3: The route resolves to /harvest-central and the grid renders with Field, Variety, No Of Harvest Tickets, Updated By, Updated By Date and Action columns. | I3: P1 | J3: Functional | K3: 12 | L3: Not Run
A4: HC-002 | B4: Harvest Central | C4: List - Data | D4: Web | E4: Harvest Central list open | F4: Verify one row exists per field/variety combination | G4: 1. Inspect rows for a field that carries multiple varieties | H4: Each field/variety combination is a separate row with its own ticket count and no duplicate rows exist. | I4: P1 | J4: Data | K4: 20 | L4: Not Run
A5: HC-003 | B5: Harvest Central | C5: List - Data | D5: Web | E5: Harvest Central list open | F5: Verify 'No Of Harvest Tickets' matches the detail view | G5: 1. Note the ticket count on a row 2. Open the row detail and count the tickets | H5: The count on the list equals the number of tickets in the detail grid for every row checked. | I5: P1 | J5: Data | K5: 20 | L5: Not Run
